Workbook

Sheet Lista
A1: RUT | B1: IDENTIFICACIÓN | C1: SECCIÓN BANNER | D1: SECCIÓN | E1: GRUPO | F1: MAIL UANDES
A2: 21222465-0 | B2: BASULTO/PEREIRA/VICENTE JOSE | C2: 1 | D2: 1 | E2: 6 | F2: vjbasulto@miuandes.cl
A3: 21952179-0 | B3: BERGUÑO/ALVAREZ/ISABELA PAZ | C3: 1 | D3: 1 | E3: 10 | F3: ipberguno@miuandes.cl
A4: 21879129-8 | B4: BOLOGNESI/AGUADO/LUCIANA | C4: 1 | D4: 1 | E4: 8 | F4: lbolognesi@miuandes.cl
A5: 21557420-2 | B5: ENCINA/DONOSO/FLORENCIA ALMENDRA | C5: 1 | D5: 1 | E5: 7 | F5: faencina@miuandes.cl
A6: 21840694-7 | B6: ESCOBAR/QUEZADA/VALENTINA PAZ | C6: 1 | D6: 1 | E6: 4 | F6: vpescobar@miuandes.cl
A7: 21268200-4 | B7: GARCIA-HUIDOBRO/FUENZALIDA/SANTIAGO TOMAS | C7: 1 | D7: 1 | E7: 5 | F7: stgarciahuidobro@miuandes.cl
A8: 21833671-K | B8: GARCIA/OLIVA/JAVIERA IGNACIA | C8: 1 | D8: 1 | E8: 3 | F8: jigarcia5@miuandes.cl
A9: 22082471-3 | B9: GIESLER/SOTO/EMILY THERESA | C9: 1 | D9: 1 | E9: 2 | F9: etgiesler@miuandes.cl
A10: 21769435-3 | B10: GOMEZ/GONZALEZ/DOMINGA ANTONIA | C10: 1 | D10: 1 | E10: 9 | F10: dagomez8@miuandes.cl
A11: 21678275-5 | B11: GONZALEZ/ALCERRECA/SOFIA TEODORA | C11: 1 | D11: 1 | E11: 4 | F11: stgonzalez1@miuandes.cl
A12: 21905344-4 | B12: GORDON/GARCIA/MARIA JESUS | C12: 1 | D12: 1 | E12: 4 | F12: mjgordon@miuandes.cl
A13: 21845775-4 | B13: JIMENEZ/ANDREU/VICTORIA PAZ | C13: 1 | D13: 1 | E13: 5 | F13: vpjimenez@miuandes.cl
... A81: 21717140-7 | B81: WOODYATT/ULRIKSEN/MARIA MARTINA | C81: 2 | D81: 2 | E81: 17 | F81: mmwoodyatt@miuandes.cl
C82: =COUNTIF(C$2:C$81,"1") -> 45 | D82: =COUNTIF(D$2:D$81,"1") -> 43 | F82: mmwoodyatt@miuandes.cl
C83: =COUNTIF(C$2:C$81,"2") -> 35 | D83: =COUNTIF(D$2:D$81,"2") -> 37

Sheet Grupos 1
A1: G1 | B1: MUNRO/LASO/ISIDORA . | C1: 1
A2: G1 | B2: MORALES/KULM/MARTINA ANDREA | C2: 1
A3: G1 | B3: PEREZ/ESPINOZA/IGNACIA JOSEFINA | C3: 1
A4: G1 | B4: SEPULVEDA/HERNANDEZ/LAURA ALEJANDRA | C4: 1
A5: G1 | B5: STONE/MURUA/VALENTINA IGNACIA | C5: 1
A6: G2 | B6: GIESLER/SOTO/EMILY THERESA | C6: 2
A7: G2 | B7: PICO/CASTRO/SIMONE PAZ | C7: 2
A8: G2 | B8: RAMOS/NIÑO/ADRIAN MAURICIO | C8: 2
A9: G2 | B9: STUARDO/FOURCADE/MARTINA NICOLE | C9: 2
A10: G2 | B10: LOPEZ/RETAMAL/JOSEFINA ESPERANZA | C10: 2
A11: G3 | B11: TAIBE/DONOSO/PAULA ANTONIA | C11: 3
A12: G3 | B12: GARCIA/OLIVA/JAVIERA IGNACIA | C12: 3
... A43: G10 | B43: SCHURCH/ZEINER/ALINE | C43: 10

Sheet Grupos 2
A1: G1 | B1: LATORRE/AHUMADA/JOSEFA | C1: 11
A2: G1 | B2: SOTOMAYOR/MESTRE/SEBASTIAN IGNACIO | C2: 11
A3: G1 | B3: ROBESON/CARVALLO/MARIA | C3: 11
A4: G1 | B4: CAÑETE/OCAMPO/ROSARIO PAZ | C4: 11
A5: G1 | B5: CARO/TRONCOSO/MARTINA LORETO | C5: 11
A6: G2 | B6: LIM/ARIAS/FLORENCIA AUGUSTA | C6: 12
A7: G2 | B7: GARRIGA/ARGANDOÑA/BENJAMIN IAIR | C7: 12
A8: G2 | B8: HERRERA/PADILLA/LAURA ISABEL | C8: 12
A9: G2 | B9: OLIVARES/PROTOPSALTIS/MANUEL NICOLAS | C9: 12
A10: G3 | B10: MORAGA/PORTILLA/MARCO ANTONIO | C10: 13
A11: G3 | B11: MUÑOZ/WILHELM/AMALIA ANDREA | C11: 13
A12: G3 | B12: HENRIQUEZ/NAWRATH/KALA | C12: 13
... A41: G10 | B41: SEMPREVIVO/GROHNERT/COLOMBA MACARENA | C41: 20

Sheet Grupos
B1: SECCIÓN 1 | E1: SECCIÓN 2
A3: G1 | B3: MUNRO/LASO/ISIDORA . | D3: G11 | E3: LATORRE/AHUMADA/JOSEFA
B4: MORALES/KULM/MARTINA ANDREA | E4: SOTOMAYOR/MESTRE/SEBASTIAN IGNACIO
B5: PEREZ/ESPINOZA/IGNACIA JOSEFINA | E5: ROBESON/CARVALLO/MARIA
B6: SEPULVEDA/HERNANDEZ/LAURA ALEJANDRA | E6: CAÑETE/OCAMPO/ROSARIO PAZ
B7: STONE/MURUA/VALENTINA IGNACIA | E7: CARO/TRONCOSO/MARTINA LORETO
A9: G2 | B9: GIESLER/SOTO/EMILY THERESA | D9: G12 | E9: LIM/ARIAS/FLORENCIA AUGUSTA
B10: PICO/CASTRO/SIMONE PAZ | E10: GARRIGA/ARGANDOÑA/BENJAMIN IAIR
B11: RAMOS/NIÑO/ADRIAN MAURICIO | E11: HERRERA/PADILLA/LAURA ISABEL
B12: STUARDO/FOURCADE/MARTINA NICOLE | E12: OLIVARES/PROTOPSALTIS/MANUEL NICOLAS
B13: LOPEZ/RETAMAL/JOSEFINA ESPERANZA
A15: G3 | B15: TAIBE/DONOSO/PAULA ANTONIA | D15: G13 | E15: MUÑOZ/WILHELM/AMALIA ANDREA
B16: GARCIA/OLIVA/JAVIERA IGNACIA | E16: HENRIQUEZ/NAWRATH/KALA
B17: PASCUAL /VARAS/CRISTINA ANDREA | E17: CHADE/ARIAS/MARIO EDUARDO
B18: MORAGA/CASTRO/CRISTIAN EDUARDO
B19: LOPEZ/THAYER/GABRIEL AMAI
A21: G4 | B21: URETA/PAVEZ/MARIA JOSE | D21: G14 | E21: NORERO/RUBIO/AMANDA
B22: GORDON/GARCIA/MARIA JESUS | E22: MARTINEZ/LETELIER/PABLO
B23: GONZALEZ/ALCERRECA/SOFIA TEODORA | E23: DIEZ/MORENO/MAGDALENA ISABEL
B24: ESCOBAR/QUEZADA/VALENTINA PAZ | E24: WILSON/GREZ/ANWAR CRISTOBAL
A27: G5 | B27: JIMENEZ/ANDREU/VICTORIA PAZ | D27: G15 | E27: ANGELLOTTI/MARTINEZ/RAIMUNDO TOMAS
B28: MATURANA/FUENTES/ALEX DANIEL | E28: SANTELICES/SAINZ/TOMAS FELIPE
B29: GARCIA-HUIDOBRO/FUENZALIDA/SANTIAGO TOMAS | E29: DIAZ/FORNI/FERNANDA JESUS
B30: MARTINEZ/AGUILAR/SEBASTIAN PABLO
A33: G6 | B33: BASULTO/PEREIRA/VICENTE JOSE | D33: G16 | E33: BIZE/HENRIQUEZ/CRISTOBAL IGNACIO
B34: REBOLLEDO/TOMICIC/AGUSTINA ELVIRA | E34: SILVA/ROJAS/DIEGO ALONSO
B35: RATTO/ESCOBAR/JAVIER BENJAMIN | E35: RODRIGUEZ/CARREÑO/ANTONIA SOFIA
B36: SAHADY/MOLINA/FERNANDO JAVIER | E36: LAVIN/VALLEJOS/IGNACIA MARIA
A39: G7 | B39: SCHNEIDER/RUIZ DE VIÑASPRE/CATALINA URSULA | D39: G17 | E39: WOODYATT/ULRIKSEN/MARIA MARTINA
B40: ENCINA/DONOSO/FLORENCIA ALMENDRA | E40: BUSTAMANTE/CARTAGENA/VANESSA EMILIA
B41: NUÑEZ/ROMERO/VICENTE ANDRES | E41: TORO/SEPULVEDA/JOSE EDUARDO
B42: MIRANDA/MITCHEL/PABLO SEBASTIAN | E42: IZQUIERDO/MONTES/RAFAEL IGNACIO
A45: G8 | B45: BOLOGNESI/AGUADO/LUCIANA | D45: G18 | E45: ROJAS/MASSARDO/OSVALDO IGNACIO
B46: SIMONET/BUSTOS/MARTINA SOFIA | E46: DIAZ/ALLAIN/PABLO ANDRES
B47: ROA/RUBILAR/FRANCISCO IGNACIO
B48: MALDONADO/ARCE/SOFIA ANTONIA
A51: G9 | B51: SOTO/LOBOS/RENATA IGNACIA | D51: G19 | E51: BRIONES/MEZA/DIEGO ANTONIO
B52: VEGA/SUAREZ/PAZ ANTONIA | E52: MILLACURA/VALENZUELA/BENJAMIN PABLO
B53: ORELLANA/CACHICH/ALBERTO ISA | E53: JULLIAN/EYZAGUIRRE/BARBARA
B54: GOMEZ/GONZALEZ/DOMINGA ANTONIA | E54: BENITEZ/RAMIREZ/JOAQUIN IGNACIO
...

Sheet Asistencia
A1: RUT | B1: IDENTIFICACIÓN | C1: GRUPO | D1: SECCION | E1: TALLER 1 | F1: TALLER 2 | G1: TALLER 3 | H1: TALLER 4 | I1: LAB 1 | J1: % ASISTENCIA
A2: 21222465-0 | B2: BASULTO/PEREIRA/VICENTE JOSE | C2: =VLOOKUP(B2,'Grupos 1'!B:C,2,FALSE) -> 6 | D2: 1 | E2: x | F2: x | G2: x | H2: x | I2: x | J2: =COUNTIF(E2:I2,"X")/(COUNTIF(E2:I2,"X")+COUNTIF(E2:I2,"I")) -> 1
A3: 21952179-0 | B3: BERGUÑO/ALVAREZ/ISABELA PAZ | C3: =VLOOKUP(B3,'Grupos 1'!B:C,2,FALSE) -> 10 | D3: 1 | E3: x | F3: x | G3: x | H3: x | I3: x | J3: =COUNTIF(E3:I3,"X")/(COUNTIF(E3:I3,"X")+COUNTIF(E3:I3,"I")) -> 1
A4: 21879129-8 | B4: BOLOGNESI/AGUADO/LUCIANA | C4: =VLOOKUP(B4,'Grupos 1'!B:C,2,FALSE) -> 8 | D4: 1 | E4: x | F4: x | G4: x | H4: x | I4: x | J4: =COUNTIF(E4:I4,"X")/(COUNTIF(E4:I4,"X")+COUNTIF(E4:I4,"I")) -> 1
A5: 21557420-2 | B5: ENCINA/DONOSO/FLORENCIA ALMENDRA | C5: =VLOOKUP(B5,'Grupos 1'!B:C,2,FALSE) -> 7 | D5: 1 | E5: x | F5: x | G5: x | H5: x | I5: x | J5: =COUNTIF(E5:I5,"X")/(COUNTIF(E5:I5,"X")+COUNTIF(E5:I5,"I")) -> 1
A6: 21840694-7 | B6: ESCOBAR/QUEZADA/VALENTINA PAZ | C6: =VLOOKUP(B6,'Grupos 1'!B:C,2,FALSE) -> 4 | D6: 1 | E6: x | F6: x | G6: x | H6: x | I6: J | J6: =COUNTIF(E6:I6,"X")/(COUNTIF(E6:I6,"X")+COUNTIF(E6:I6,"I")) -> 1
A7: 21268200-4 | B7: GARCIA-HUIDOBRO/FUENZALIDA/SANTIAGO TOMAS | C7: =VLOOKUP(B7,'Grupos 1'!B:C,2,FALSE) -> 5 | D7: 1 | E7: x | F7: x | G7: x | H7: x | I7: x | J7: =COUNTIF(E7:I7,"X")/(COUNTIF(E7:I7,"X")+COUNTIF(E7:I7,"I")) -> 1
A8: 21833671-K | B8: GARCIA/OLIVA/JAVIERA IGNACIA | C8: =VLOOKUP(B8,'Grupos 1'!B:C,2,FALSE) -> 3 | D8: 1 | E8: x | F8: x | G8: x | H8: x | I8: x | J8: =COUNTIF(E8:I8,"X")/(COUNTIF(E8:I8,"X")+COUNTIF(E8:I8,"I")) -> 1
A9: 22082471-3 | B9: GIESLER/SOTO/EMILY THERESA | C9: =VLOOKUP(B9,'Grupos 1'!B:C,2,FALSE) -> 2 | D9: 1 | E9: x | F9: x | G9: x | H9: x | I9: x | J9: =COUNTIF(E9:I9,"X")/(COUNTIF(E9:I9,"X")+COUNTIF(E9:I9,"I")) -> 1
A10: 21769435-3 | B10: GOMEZ/GONZALEZ/DOMINGA ANTONIA | C10: =VLOOKUP(B10,'Grupos 1'!B:C,2,FALSE) -> 9 | D10: 1 | E10: x | F10: x | G10: J | H10: x | I10: x | J10: =COUNTIF(E10:I10,"X")/(COUNTIF(E10:I10,"X")+COUNTIF(E10:I10,"I")) -> 1
A11: 21678275-5 | B11: GONZALEZ/ALCERRECA/SOFIA TEODORA | C11: =VLOOKUP(B11,'Grupos 1'!B:C,2,FALSE) -> 4 | D11: 1 | E11: x | F11: x | G11: x | H11: x | I11: x | J11: =COUNTIF(E11:I11,"X")/(COUNTIF(E11:I11,"X")+COUNTIF(E11:I11,"I")) -> 1
A12: 21905344-4 | B12: GORDON/GARCIA/MARIA JESUS | C12: =VLOOKUP(B12,'Grupos 1'!B:C,2,FALSE) -> 4 | D12: 1 | E12: x | F12: x | G12: x | H12: x | I12: x | J12: =COUNTIF(E12:I12,"X")/(COUNTIF(E12:I12,"X")+COUNTIF(E12:I12,"I")) -> 1
A13: 21845775-4 | B13: JIMENEZ/ANDREU/VICTORIA PAZ | C13: =VLOOKUP(B13,'Grupos 1'!B:C,2,FALSE) -> 5 | D13: 1 | E13: x | F13: x | G13: x | H13: x | I13: x | J13: =COUNTIF(E13:I13,"X")/(COUNTIF(E13:I13,"X")+COUNTIF(E13:I13,"I")) -> 1
... A44: 21822834-8 | B44: VEGA/SUAREZ/PAZ ANTONIA | C44: =VLOOKUP(B44,'Grupos 1'!B:C,2,FALSE) -> 9 | D44: 1 | E44: x | F44: x | G44: x | H44: x | I44: x | J44: =COUNTIF(E44:I44,"X")/(COUNTIF(E44:I44,"X")+COUNTIF(E44:I44,"I")) -> 1
A45: 21043404-6 | B45: ANGELLOTTI/MARTINEZ/RAIMUNDO TOMAS | C45: =VLOOKUP(B45,'Grupos 2'!B:C,2,FALSE) -> 15 | D45: 2 | E45: x | F45: x | G45: x | H45: x | I45: x | J45: =COUNTIF(E45:I45,"X")/(COUNTIF(E45:I45,"X")+COUNTIF(E45:I45,"I")) -> 1
A46: 21708911-5 | B46: BENITEZ/RAMIREZ/JOAQUIN IGNACIO | C46: =VLOOKUP(B46,'Grupos 2'!B:C,2,FALSE) -> 19 | D46: 2 | E46: J | F46: x | G46: x | H46: x | I46: x | J46: =COUNTIF(E46:I46,"X")/(COUNTIF(E46:I46,"X")+COUNTIF(E46:I46,"I")) -> 1
A47: 21792244-5 | B47: BIZE/HENRIQUEZ/CRISTOBAL IGNACIO | C47: =VLOOKUP(B47,'Grupos 2'!B:C,2,FALSE) -> 16 | D47: 2 | E47: x | F47: x | G47: x | H47: x | I47: x | J47: =COUNTIF(E47:I47,"X")/(COUNTIF(E47:I47,"X")+COUNTIF(E47:I47,"I")) -> 1
A48: 21566004-4 | B48: BRIONES/MEZA/DIEGO ANTONIO | C48: =VLOOKUP(B48,'Grupos 2'!B:C,2,FALSE) -> 19 | D48: 2 | E48: x | F48: x | G48: x | H48: x | I48: x | J48: =COUNTIF(E48:I48,"X")/(COUNTIF(E48:I48,"X")+COUNTIF(E48:I48,"I")) -> 1
A49: 21896364-1 | B49: BUSTAMANTE/CARTAGENA/VANESSA EMILIA | C49: =VLOOKUP(B49,'Grupos 2'!B:C,2,FALSE) -> 17 | D49: 2 | E49: x | F49: x | G49: x | H49: x | I49: x | J49: =COUNTIF(E49:I49,"X")/(COUNTIF(E49:I49,"X")+COUNTIF(E49:I49,"I")) -> 1
A50: 21149692-4 | B50: CAÑETE/OCAMPO/ROSARIO PAZ | C50: =VLOOKUP(B50,'Grupos 2'!B:C,2,FALSE) -> 11 | D50: 2 | E50: x | F50: x | G50: I | H50: x | I50: x | J50: =COUNTIF(E50:I50,"X")/(COUNTIF(E50:I50,"X")+COUNTIF(E50:I50,"I")) -> 0.8
A51: 22030122-2 | B51: CARO/TRONCOSO/MARTINA LORETO | C51: =VLOOKUP(B51,'Grupos 2'!B:C,2,FALSE) -> 11 | D51: 2 | E51: x | F51: x | G51: x | H51: x | I51: x | J51: =COUNTIF(E51:I51,"X")/(COUNTIF(E51:I51,"X")+COUNTIF(E51:I51,"I")) -> 1
A52: 21840696-3 | B52: CHADE/ARIAS/MARIO EDUARDO | C52: =VLOOKUP(B52,'Grupos 2'!B:C,2,FALSE) -> 13 | D52: 2 | E52: x | F52: x | G52: x | H52: x | I52: x | J52: =COUNTIF(E52:I52,"X")/(COUNTIF(E52:I52,"X")+COUNTIF(E52:I52,"I")) -> 1
A53: 21559935-3 | B53: DIAZ/ALLAIN/PABLO ANDRES | C53: =VLOOKUP(B53,'Grupos 2'!B:C,2,FALSE) -> 18 | D53: 2 | E53: x | F53: x | G53: x | H53: x | I53: x | J53: =COUNTIF(E53:I53,"X")/(COUNTIF(E53:I53,"X")+COUNTIF(E53:I53,"I")) -> 1
A54: 21988754-K | B54: DIAZ/FORNI/FERNANDA JESUS | C54: =VLOOKUP(B54,'Grupos 2'!B:C,2,FALSE) -> 15 | D54: 2 | E54: x | F54: x | G54: x | H54: x | I54: x | J54: =COUNTIF(E54:I54,"X")/(COUNTIF(E54:I54,"X")+COUNTIF(E54:I54,"I")) -> 1
A55: 22046076-2 | B55: DIEZ/MORENO/MAGDALENA ISABEL | C55: =VLOOKUP(B55,'Grupos 2'!B:C,2,FALSE) -> 14 | D55: 2 | E55: x | F55: x | G55: x | H55: x | I55: x | J55: =COUNTIF(E55:I55,"X")/(COUNTIF(E55:I55,"X")+COUNTIF(E55:I55,"I")) -> 1
A56: 21893593-1 | B56: GARRIGA/ARGANDOÑA/BENJAMIN IAIR | C56: =VLOOKUP(B56,'Grupos 2'!B:C,2,FALSE) -> 12 | D56: 2 | E56: x | F56: x | G56: x | H56: x | I56: x | J56: =COUNTIF(E56:I56,"X")/(COUNTIF(E56:I56,"X")+COUNTIF(E56:I56,"I")) -> 1
... A81: 21717140-7 | B81: WOODYATT/ULRIKSEN/MARIA MARTINA | C81: =VLOOKUP(B81,'Grupos 2'!B:C,2,FALSE) -> 17 | D81: 2 | E81: x | F81: x | G81: x | H81: x | I81: x | J81: =COUNTIF(E81:I81,"X")/(COUNTIF(E81:I81,"X")+COUNTIF(E81:I81,"I")) -> 1

Sheet Prueba 1
A1: RUT | B1: IDENTIFICACIÓN | C1: SECCIÓN | D1: ALTERNATIVAS | E1: DESARROLLO | F1: Asistencia Jornada | G1: TOTAL | H1: NOTA
A2: 21043404-6 | B2: ANGELLOTTI/MARTINEZ/RAIMUNDO TOMAS | C2: 2 | D2: 33 | E2: 16 | F2: 1 | G2: =SUM(D2:F2) -> 50 | H2: =IF(IF(G2>=$K$4*0.6,3*(((G2/$K$4)*100-60)/(100-60))+4,3*(G2/($K$4*0.6))+1)>7,7,IF(G2>=$K$4*0.6,3*(((G2/$K$4)*100-60)/(100-60))+4,3*(G2/($K$4*0.6))+1)) -> 5.75 | J2: Puntaje ideal | K2: 64
A3: 21222465-0 | B3: BASULTO/PEREIRA/VICENTE JOSE | C3: 1 | D3: 23 | E3: 2 | F3: 1 | G3: =SUM(D3:F3) -> 26 | H3: =IF(IF(G3>=$K$4*0.6,3*(((G3/$K$4)*100-60)/(100-60))+4,3*(G3/($K$4*0.6))+1)>7,7,IF(G3>=$K$4*0.6,3*(((G3/$K$4)*100-60)/(100-60))+4,3*(G3/($K$4*0.6))+1)) -> 3.1666667 | J3: Puntaje real | K3: =MAX(G:G) -> 56
A4: 21708911-5 | B4: BENITEZ/RAMIREZ/JOAQUIN IGNACIO | C4: 2 | D4: 13 | E4: 4 | G4: =SUM(D4:F4) -> 17 | H4: =IF(IF(G4>=$K$4*0.6,3*(((G4/$K$4)*100-60)/(100-60))+4,3*(G4/($K$4*0.6))+1)>7,7,IF(G4>=$K$4*0.6,3*(((G4/$K$4)*100-60)/(100-60))+4,3*(G4/($K$4*0.6))+1)) -> 2.4166667 | J4: Puntaje final | K4: 60
A5: 21952179-0 | B5: BERGUÑO/ALVAREZ/ISABELA PAZ | C5: 1 | D5: 36 | E5: 17 | F5: 1 | G5: =SUM(D5:F5) -> 54 | H5: =IF(IF(G5>=$K$4*0.6,3*(((G5/$K$4)*100-60)/(100-60))+4,3*(G5/($K$4*0.6))+1)>7,7,IF(G5>=$K$4*0.6,3*(((G5/$K$4)*100-60)/(100-60))+4,3*(G5/($K$4*0.6))+1)) -> 6.25
A6: 21792244-5 | B6: BIZE/HENRIQUEZ/CRISTOBAL IGNACIO | C6: 2 | D6: 29 | E6: 14.5 | G6: =SUM(D6:F6) -> 43.5 | H6: =IF(IF(G6>=$K$4*0.6,3*(((G6/$K$4)*100-60)/(100-60))+4,3*(G6/($K$4*0.6))+1)>7,7,IF(G6>=$K$4*0.6,3*(((G6/$K$4)*100-60)/(100-60))+4,3*(G6/($K$4*0.6))+1)) -> 4.9375
A7: 21879129-8 | B7: BOLOGNESI/AGUADO/LUCIANA | C7: 1 | D7: 24 | E7: 13 | G7: =SUM(D7:F7) -> 37 | H7: =IF(IF(G7>=$K$4*0.6,3*(((G7/$K$4)*100-60)/(100-60))+4,3*(G7/($K$4*0.6))+1)>7,7,IF(G7>=$K$4*0.6,3*(((G7/$K$4)*100-60)/(100-60))+4,3*(G7/($K$4*0.6))+1)) -> 4.125
A8: 21566004-4 | B8: BRIONES/MEZA/DIEGO ANTONIO | C8: 2 | D8: 13 | E8: 3 | G8: =SUM(D8:F8) -> 16 | H8: =IF(IF(G8>=$K$4*0.6,3*(((G8/$K$4)*100-60)/(100-60))+4,3*(G8/($K$4*0.6))+1)>7,7,IF(G8>=$K$4*0.6,3*(((G8/$K$4)*100-60)/(100-60))+4,3*(G8/($K$4*0.6))+1)) -> 2.3333333
A9: 21896364-1 | B9: BUSTAMANTE/CARTAGENA/VANESSA EMILIA | C9: 2 | D9: 22 | E9: 12 | F9: 1 | G9: =SUM(D9:F9) -> 35 | H9: =IF(IF(G9>=$K$4*0.6,3*(((G9/$K$4)*100-60)/(100-60))+4,3*(G9/($K$4*0.6))+1)>7,7,IF(G9>=$K$4*0.6,3*(((G9/$K$4)*100-60)/(100-60))+4,3*(G9/($K$4*0.6))+1)) -> 3.9166667
A10: 21149692-4 | B10: CAÑETE/OCAMPO/ROSARIO PAZ | C10: 2 | D10: 27 | E10: 15 | F10: 1 | G10: =SUM(D10:F10) -> 43 | H10: =IF(IF(G10>=$K$4*0.6,3*(((G10/$K$4)*100-60)/(100-60))+4,3*(G10/($K$4*0.6))+1)>7,7,IF(G10>=$K$4*0.6,3*(((G10/$K$4)*100-60)/(100-60))+4,3*(G10/($K$4*0.6))+1)) -> 4.875
A11: 22030122-2 | B11: CARO/TRONCOSO/MARTINA LORETO | C11: 2 | D11: 30 | E11: 18 | F11: 1 | G11: =SUM(D11:F11) -> 49 | H11: =IF(IF(G11>=$K$4*0.6,3*(((G11/$K$4)*100-60)/(100-60))+4,3*(G11/($K$4*0.6))+1)>7,7,IF(G11>=$K$4*0.6,3*(((G11/$K$4)*100-60)/(100-60))+4,3*(G11/($K$4*0.6))+1)) -> 5.625
A12: 21840696-3 | B12: CHADE/ARIAS/MARIO EDUARDO | C12: 2 | D12: 27 | E12: 9 | F12: 1 | G12: =SUM(D12:F12) -> 37 | H12: =IF(IF(G12>=$K$4*0.6,3*(((G12/$K$4)*100-60)/(100-60))+4,3*(G12/($K$4*0.6))+1)>7,7,IF(G12>=$K$4*0.6,3*(((G12/$K$4)*100-60)/(100-60))+4,3*(G12/($K$4*0.6))+1)) -> 4.125
A13: 21559935-3 | B13: DIAZ/ALLAIN/PABLO ANDRES | C13: 2 | D13: 26 | E13: 13 | F13: 1 | G13: =SUM(D13:F13) -> 40 | H13: =IF(IF(G13>=$K$4*0.6,3*(((G13/$K$4)*100-60)/(100-60))+4,3*(G13/($K$4*0.6))+1)>7,7,IF(G13>=$K$4*0.6,3*(((G13/$K$4)*100-60)/(100-60))+4,3*(G13/($K$4*0.6))+1)) -> 4.5
A14: 21988754-K | B14: DIAZ/FORNI/FERNANDA JESUS | C14: 2 | D14: 31 | E14: 12.5 | F14: 1 | G14: =SUM(D14:F14) -> 44.5 | H14: =IF(IF(G14>=$K$4*0.6,3*(((G14/$K$4)*100-60)/(100-60))+4,3*(G14/($K$4*0.6))+1)>7,7,IF(G14>=$K$4*0.6,3*(((G14/$K$4)*100-60)/(100-60))+4,3*(G14/($K$4*0.6))+1)) -> 5.0625
A15: 22046076-2 | B15: DIEZ/MORENO/MAGDALENA ISABEL | C15: 2 | D15: 25 | E15: 10 | F15: 1 | G15: =SUM(D15:F15) -> 36 | H15: =IF(IF(G15>=$K$4*0.6,3*(((G15/$K$4)*100-60)/(100-60))+4,3*(G15/($K$4*0.6))+1)>7,7,IF(G15>=$K$4*0.6,3*(((G15/$K$4)*100-60)/(100-60))+4,3*(G15/($K$4*0.6))+1)) -> 4
A16: 21557420-2 | B16: ENCINA/DONOSO/FLORENCIA ALMENDRA | C16: 1 | D16: 16 | E16: 4 | G16: =SUM(D16:F16) -> 20 | H16: =IF(IF(G16>=$K$4*0.6,3*(((G16/$K$4)*100-60)/(100-60))+4,3*(G16/($K$4*0.6))+1)>7,7,IF(G16>=$K$4*0.6,3*(((G16/$K$4)*100-60)/(100-60))+4,3*(G16/($K$4*0.6))+1)) -> 2.6666667
A17: 21840694-7 | B17: ESCOBAR/QUEZADA/VALENTINA PAZ | C17: 1 | D17: 35 | E17: 14.5 | F17: 1 | G17: =SUM(D17:F17) -> 50.5 | H17: =IF(IF(G17>=$K$4*0.6,3*(((G17/$K$4)*100-60)/(100-60))+4,3*(G17/($K$4*0.6))+1)>7,7,IF(G17>=$K$4*0.6,3*(((G17/$K$4)*100-60)/(100-60))+4,3*(G17/($K$4*0.6))+1)) -> 5.8125
A18: 21268200-4 | B18: GARCIA-HUIDOBRO/FUENZALIDA/SANTIAGO TOMAS | C18: 1 | D18: 34 | E18: 17.5 | G18: =SUM(D18:F18) -> 51.5 | H18: =IF(IF(G18>=$K$4*0.6,3*(((G18/$K$4)*100-60)/(100-60))+4,3*(G18/($K$4*0.6))+1)>7,7,IF(G18>=$K$4*0.6,3*(((G18/$K$4)*100-60)/(100-60))+4,3*(G18/($K$4*0.6))+1)) -> 5.9375
A19: 21833671-K | B19: GARCIA/OLIVA/JAVIERA IGNACIA | C19: 1 | D19: 22 | E19: 6 | G19: =SUM(D19:F19) -> 28 | H19: =IF(IF(G19>=$K$4*0.6,3*(((G19/$K$4)*100-60)/(100-60))+4,3*(G19/($K$4*0.6))+1)>7,7,IF(G19>=$K$4*0.6,3*(((G19/$K$4)*100-60)/(100-60))+4,3*(G19/($K$4*0.6))+1)) -> 3.3333333
A20: 21893593-1 | B20: GARRIGA/ARGANDOÑA/BENJAMIN IAIR | C20: 2 | D20: 18 | E20: 4 | F20: 1 | G20: =SUM(D20:F20) -> 23 | H20: =IF(IF(G20>=$K$4*0.6,3*(((G20/$K$4)*100-60)/(100-60))+4,3*(G20/($K$4*0.6))+1)>7,7,IF(G20>=$K$4*0.6,3*(((G20/$K$4)*100-60)/(100-60))+4,3*(G20/($K$4*0.6))+1)) -> 2.9166667
A21: 22082471-3 | B21: GIESLER/SOTO/EMILY THERESA | C21: 1 | D21: 31 | E21: 3 | F21: 1 | G21: =SUM(D21:F21) -> 35 | H21: =IF(IF(G21>=$K$4*0.6,3*(((G21/$K$4)*100-60)/(100-60))+4,3*(G21/($K$4*0.6))+1)>7,7,IF(G21>=$K$4*0.6,3*(((G21/$K$4)*100-60)/(100-60))+4,3*(G21/($K$4*0.6))+1)) -> 3.9166667
A22: 21769435-3 | B22: GOMEZ/GONZALEZ/DOMINGA ANTONIA | C22: 1 | D22: 19 | E22: 2 | F22: 1 | G22: =SUM(D22:F22) -> 22 | H22: =IF(IF(G22>=$K$4*0.6,3*(((G22/$K$4)*100-60)/(100-60))+4,3*(G22/($K$4*0.6))+1)>7,7,IF(G22>=$K$4*0.6,3*(((G22/$K$4)*100-60)/(100-60))+4,3*(G22/($K$4*0.6))+1)) -> 2.8333333
A23: 21678275-5 | B23: GONZALEZ/ALCERRECA/SOFIA TEODORA | C23: 1 | D23: 16 | E23: 3 | G23: =SUM(D23:F23) -> 19 | H23: =IF(IF(G23>=$K$4*0.6,3*(((G23/$K$4)*100-60)/(100-60))+4,3*(G23/($K$4*0.6))+1)>7,7,IF(G23>=$K$4*0.6,3*(((G23/$K$4)*100-60)/(100-60))+4,3*(G23/($K$4*0.6))+1)) -> 2.5833333
A24: 21905344-4 | B24: GORDON/GARCIA/MARIA JESUS | C24: 1 | D24: 17 | E24: 5.5 | F24: 1 | G24: =SUM(D24:F24) -> 23.5 | H24: =IF(IF(G24>=$K$4*0.6,3*(((G24/$K$4)*100-60)/(100-60))+4,3*(G24/($K$4*0.6))+1)>7,7,IF(G24>=$K$4*0.6,3*(((G24/$K$4)*100-60)/(100-60))+4,3*(G24/($K$4*0.6))+1)) -> 2.9583333
A25: 21865263-8 | B25: HENRIQUEZ/NAWRATH/KALA | C25: 2 | D25: 27 | E25: 12 | F25: 1 | G25: =SUM(D25:F25) -> 40 | H25: =IF(IF(G25>=$K$4*0.6,3*(((G25/$K$4)*100-60)/(100-60))+4,3*(G25/($K$4*0.6))+1)>7,7,IF(G25>=$K$4*0.6,3*(((G25/$K$4)*100-60)/(100-60))+4,3*(G25/($K$4*0.6))+1)) -> 4.5
A26: 21816695-4 | B26: HERRERA/PADILLA/LAURA ISABEL | C26: 2 | D26: 28 | E26: 11 | F26: 1 | G26: =SUM(D26:F26) -> 40 | H26: =IF(IF(G26>=$K$4*0.6,3*(((G26/$K$4)*100-60)/(100-60))+4,3*(G26/($K$4*0.6))+1)>7,7,IF(G26>=$K$4*0.6,3*(((G26/$K$4)*100-60)/(100-60))+4,3*(G26/($K$4*0.6))+1)) -> 4.5
A27: 22011859-2 | B27: PEREZ/HOWARD/CRISTOBAL ANDRES | C27: 2 | D27: 26 | E27: 18 | G27: =SUM(D27:F27) -> 44 | H27: =IF(IF(G27>=$K$4*0.6,3*(((G27/$K$4)*100-60)/(100-60))+4,3*(G27/($K$4*0.6))+1)>7,7,IF(G27>=$K$4*0.6,3*(((G27/$K$4)*100-60)/(100-60))+4,3*(G27/($K$4*0.6))+1)) -> 5
A28: 21624852-K | B28: IZQUIERDO/MONTES/RAFAEL IGNACIO | C28: 2 | D28: 13 | E28: 5 | F28: 1 | G28: =SUM(D28:F28) -> 19 | H28: =IF(IF(G28>=$K$4*0.6,3*(((G28/$K$4)*100-60)/(100-60))+4,3*(G28/($K$4*0.6))+1)>7,7,IF(G28>=$K$4*0.6,3*(((G28/$K$4)*100-60)/(100-60))+4,3*(G28/($K$4*0.6))+1)) -> 2.5833333
A29: 21845775-4 | B29: JIMENEZ/ANDREU/VICTORIA PAZ | C29: 1 | D29: 31 | E29: 11.5 | F29: 1 | G29: =SUM(D29:F29) -> 43.5 | H29: =IF(IF(G29>=$K$4*0.6,3*(((G29/$K$4)*100-60)/(100-60))+4,3*(G29/($K$4*0.6))+1)>7,7,IF(G29>=$K$4*0.6,3*(((G29/$K$4)*100-60)/(100-60))+4,3*(G29/($K$4*0.6))+1)) -> 4.9375
A30: 21678194-5 | B30: JULLIAN/EYZAGUIRRE/BARBARA | C30: 2 | D30: 33 | E30: 17.5 | G30: =SUM(D30:F30) -> 50.5 | H30: =IF(IF(G30>=$K$4*0.6,3*(((G30/$K$4)*100-60)/(100-60))+4,3*(G30/($K$4*0.6))+1)>7,7,IF(G30>=$K$4*0.6,3*(((G30/$K$4)*100-60)/(100-60))+4,3*(G30/($K$4*0.6))+1)) -> 5.8125
A31: 21853700-6 | B31: LATORRE/AHUMADA/JOSEFA | C31: 2 | D31: 27 | E31: 7 | F31: 1 | G31: =SUM(D31:F31) -> 35 | H31: =IF(IF(G31>=$K$4*0.6,3*(((G31/$K$4)*100-60)/(100-60))+4,3*(G31/($K$4*0.6))+1)>7,7,IF(G31>=$K$4*0.6,3*(((G31/$K$4)*100-60)/(100-60))+4,3*(G31/($K$4*0.6))+1)) -> 3.9166667
A32: 21527204-4 | B32: LAVIN/VALLEJOS/IGNACIA MARIA | C32: 2 | D32: 34 | E32: 10 | G32: =SUM(D32:F32) -> 44 | H32: =IF(IF(G32>=$K$4*0.6,3*(((G32/$K$4)*100-60)/(100-60))+4,3*(G32/($K$4*0.6))+1)>7,7,IF(G32>=$K$4*0.6,3*(((G32/$K$4)*100-60)/(100-60))+4,3*(G32/($K$4*0.6))+1)) -> 5
A33: 21923918-1 | B33: LIM/ARIAS/FLORENCIA AUGUSTA | C33: 2 | D33: 28 | E33: 8 | F33: 1 | G33: =SUM(D33:F33) -> 37 | H33: =IF(IF(G33>=$K$4*0.6,3*(((G33/$K$4)*100-60)/(100-60))+4,3*(G33/($K$4*0.6))+1)>7,7,IF(G33>=$K$4*0.6,3*(((G33/$K$4)*100-60)/(100-60))+4,3*(G33/($K$4*0.6))+1)) -> 4.125
A34: 21611454-K | B34: LOPEZ/RETAMAL/JOSEFINA ESPERANZA | C34: 1 | D34: 29 | E34: 20 | F34: 1 | G34: =SUM(D34:F34) -> 50 | H34: =IF(IF(G34>=$K$4*0.6,3*(((G34/$K$4)*100-60)/(100-60))+4,3*(G34/($K$4*0.6))+1)>7,7,IF(G34>=$K$4*0.6,3*(((G34/$K$4)*100-60)/(100-60))+4,3*(G34/($K$4*0.6))+1)) -> 5.75
A35: 21713214-2 | B35: LOPEZ/THAYER/GABRIEL AMAI | C35: 1 | D35: 32 | E35: 20 | G35: =SUM(D35:F35) -> 52 | H35: =IF(IF(G35>=$K$4*0.6,3*(((G35/$K$4)*100-60)/(100-60))+4,3*(G35/($K$4*0.6))+1)>7,7,IF(G35>=$K$4*0.6,3*(((G35/$K$4)*100-60)/(100-60))+4,3*(G35/($K$4*0.6))+1)) -> 6
A36: 21760460-5 | B36: MALDONADO/ARCE/SOFIA ANTONIA | C36: 1 | D36: 33 | E36: 8 | F36: 1 | G36: =SUM(D36:F36) -> 42 | H36: =IF(IF(G36>=$K$4*0.6,3*(((G36/$K$4)*100-60)/(100-60))+4,3*(G36/($K$4*0.6))+1)>7,7,IF(G36>=$K$4*0.6,3*(((G36/$K$4)*100-60)/(100-60))+4,3*(G36/($K$4*0.6))+1)) -> 4.75
A37: 21833415-6 | B37: MARTINEZ/AGUILAR/SEBASTIAN PABLO | C37: 1 | D37: 25 | E37: 9 | G37: =SUM(D37:F37) -> 34 | H37: =IF(IF(G37>=$K$4*0.6,3*(((G37/$K$4)*100-60)/(100-60))+4,3*(G37/($K$4*0.6))+1)>7,7,IF(G37>=$K$4*0.6,3*(((G37/$K$4)*100-60)/(100-60))+4,3*(G37/($K$4*0.6))+1)) -> 3.8333333
A38: 21926350-3 | B38: MARTINEZ/LETELIER/PABLO | C38: 2 | D38: 30 | E38: 17 | G38: =SUM(D38:F38) -> 47 | H38: =IF(IF(G38>=$K$4*0.6,3*(((G38/$K$4)*100-60)/(100-60))+4,3*(G38/($K$4*0.6))+1)>7,7,IF(G38>=$K$4*0.6,3*(((G38/$K$4)*100-60)/(100-60))+4,3*(G38/($K$4*0.6))+1)) -> 5.375
A39: 21940672-K | B39: MATURANA/FUENTES/ALEX DANIEL | C39: 1 | D39: 33 | E39: 17.5 | F39: 1 | G39: =SUM(D39:F39) -> 51.5 | H39: =IF(IF(G39>=$K$4*0.6,3*(((G39/$K$4)*100-60)/(100-60))+4,3*(G39/($K$4*0.6))+1)>7,7,IF(G39>=$K$4*0.6,3*(((G39/$K$4)*100-60)/(100-60))+4,3*(G39/($K$4*0.6))+1)) -> 5.9375
A40: 21473332-3 | B40: MILLACURA/VALENZUELA/BENJAMIN PABLO | C40: 2 | D40: 18 | E40: 12.5 | F40: 1 | G40: =SUM(D40:F40) -> 31.5 | H40: =IF(IF(G40>=$K$4*0.6,3*(((G40/$K$4)*100-60)/(100-60))+4,3*(G40/($K$4*0.6))+1)>7,7,IF(G40>=$K$4*0.6,3*(((G40/$K$4)*100-60)/(100-60))+4,3*(G40/($K$4*0.6))+1)) -> 3.625
...

Sheet Prueba 2
A1: RUT | B1: IDENTIFICACIÓN | C1: SECCIÓN | D1: ALTERNATIVAS | E1: DESARROLLO | F1: TOTAL | G1: NOTA
A2: 21043404-6 | B2: ANGELLOTTI/MARTINEZ/RAIMUNDO TOMAS | C2: 2 | D2: 38 | E2: 18.5 | F2: =SUM(D2:E2) -> 56.5 | G2: =IF(IF(F2>=$J$4*0.6,3*(((F2/$J$4)*100-60)/(100-60))+4,3*(F2/($J$4*0.6))+1)>7,7,IF(F2>=$J$4*0.6,3*(((F2/$J$4)*100-60)/(100-60))+4,3*(F2/($J$4*0.6))+1)) -> 6.5625 | I2: Puntaje ideal | J2: 62
A3: 21222465-0 | B3: BASULTO/PEREIRA/VICENTE JOSE | C3: 1 | D3: 28 | E3: 4.5 | F3: =SUM(D3:E3) -> 32.5 | G3: =IF(IF(F3>=$J$4*0.6,3*(((F3/$J$4)*100-60)/(100-60))+4,3*(F3/($J$4*0.6))+1)>7,7,IF(F3>=$J$4*0.6,3*(((F3/$J$4)*100-60)/(100-60))+4,3*(F3/($J$4*0.6))+1)) -> 3.7083333 | I3: Puntaje real | J3: =MAX(F:F) -> 58.5
A4: 21708911-5 | B4: BENITEZ/RAMIREZ/JOAQUIN IGNACIO | C4: 2 | D4: 31 | E4: 15 | F4: =SUM(D4:E4) -> 46 | G4: =IF(IF(F4>=$J$4*0.6,3*(((F4/$J$4)*100-60)/(100-60))+4,3*(F4/($J$4*0.6))+1)>7,7,IF(F4>=$J$4*0.6,3*(((F4/$J$4)*100-60)/(100-60))+4,3*(F4/($J$4*0.6))+1)) -> 5.25 | I4: Puntaje final | J4: 60
A5: 21952179-0 | B5: BERGUÑO/ALVAREZ/ISABELA PAZ | C5: 1 | D5: 32 | E5: 20 | F5: =SUM(D5:E5) -> 52 | G5: =IF(IF(F5>=$J$4*0.6,3*(((F5/$J$4)*100-60)/(100-60))+4,3*(F5/($J$4*0.6))+1)>7,7,IF(F5>=$J$4*0.6,3*(((F5/$J$4)*100-60)/(100-60))+4,3*(F5/($J$4*0.6))+1)) -> 6
A6: 21792244-5 | B6: BIZE/HENRIQUEZ/CRISTOBAL IGNACIO | C6: 2 | D6: 26 | E6: 12 | F6: =SUM(D6:E6) -> 38 | G6: =IF(IF(F6>=$J$4*0.6,3*(((F6/$J$4)*100-60)/(100-60))+4,3*(F6/($J$4*0.6))+1)>7,7,IF(F6>=$J$4*0.6,3*(((F6/$J$4)*100-60)/(100-60))+4,3*(F6/($J$4*0.6))+1)) -> 4.25
A7: 21879129-8 | B7: BOLOGNESI/AGUADO/LUCIANA | C7: 1 | D7: 22 | E7: 12.5 | F7: =SUM(D7:E7) -> 34.5 | G7: =IF(IF(F7>=$J$4*0.6,3*(((F7/$J$4)*100-60)/(100-60))+4,3*(F7/($J$4*0.6))+1)>7,7,IF(F7>=$J$4*0.6,3*(((F7/$J$4)*100-60)/(100-60))+4,3*(F7/($J$4*0.6))+1)) -> 3.875
A8: 21566004-4 | B8: BRIONES/MEZA/DIEGO ANTONIO | C8: 2 | D8: 19 | E8: 2 | F8: =SUM(D8:E8) -> 21 | G8: =IF(IF(F8>=$J$4*0.6,3*(((F8/$J$4)*100-60)/(100-60))+4,3*(F8/($J$4*0.6))+1)>7,7,IF(F8>=$J$4*0.6,3*(((F8/$J$4)*100-60)/(100-60))+4,3*(F8/($J$4*0.6))+1)) -> 2.75
A9: 21896364-1 | B9: BUSTAMANTE/CARTAGENA/VANESSA EMILIA | C9: 2 | D9: 12 | E9: 8 | F9: =SUM(D9:E9) -> 20 | G9: =IF(IF(F9>=$J$4*0.6,3*(((F9/$J$4)*100-60)/(100-60))+4,3*(F9/($J$4*0.6))+1)>7,7,IF(F9>=$J$4*0.6,3*(((F9/$J$4)*100-60)/(100-60))+4,3*(F9/($J$4*0.6))+1)) -> 2.6666667
A10: 21149692-4 | B10: CAÑETE/OCAMPO/ROSARIO PAZ | C10: 2 | D10: 29 | E10: 11 | F10: =SUM(D10:E10) -> 40 | G10: =IF(IF(F10>=$J$4*0.6,3*(((F10/$J$4)*100-60)/(100-60))+4,3*(F10/($J$4*0.6))+1)>7,7,IF(F10>=$J$4*0.6,3*(((F10/$J$4)*100-60)/(100-60))+4,3*(F10/($J$4*0.6))+1)) -> 4.5
A11: 22030122-2 | B11: CARO/TRONCOSO/MARTINA LORETO | C11: 2 | D11: 25 | E11: 17 | F11: =SUM(D11:E11) -> 42 | G11: =IF(IF(F11>=$J$4*0.6,3*(((F11/$J$4)*100-60)/(100-60))+4,3*(F11/($J$4*0.6))+1)>7,7,IF(F11>=$J$4*0.6,3*(((F11/$J$4)*100-60)/(100-60))+4,3*(F11/($J$4*0.6))+1)) -> 4.75
A12: 21840696-3 | B12: CHADE/ARIAS/MARIO EDUARDO | C12: 2 | D12: 18 | E12: 11.5 | F12: =SUM(D12:E12) -> 29.5 | G12: =IF(IF(F12>=$J$4*0.6,3*(((F12/$J$4)*100-60)/(100-60))+4,3*(F12/($J$4*0.6))+1)>7,7,IF(F12>=$J$4*0.6,3*(((F12/$J$4)*100-60)/(100-60))+4,3*(F12/($J$4*0.6))+1)) -> 3.4583333
A13: 21559935-3 | B13: DIAZ/ALLAIN/PABLO ANDRES | C13: 2 | D13: 21 | E13: 7.5 | F13: =SUM(D13:E13) -> 28.5 | G13: =IF(IF(F13>=$J$4*0.6,3*(((F13/$J$4)*100-60)/(100-60))+4,3*(F13/($J$4*0.6))+1)>7,7,IF(F13>=$J$4*0.6,3*(((F13/$J$4)*100-60)/(100-60))+4,3*(F13/($J$4*0.6))+1)) -> 3.375
A14: 21988754-K | B14: DIAZ/FORNI/FERNANDA JESUS | C14: 2 | D14: 28 | E14: 15 | F14: =SUM(D14:E14) -> 43 | G14: =IF(IF(F14>=$J$4*0.6,3*(((F14/$J$4)*100-60)/(100-60))+4,3*(F14/($J$4*0.6))+1)>7,7,IF(F14>=$J$4*0.6,3*(((F14/$J$4)*100-60)/(100-60))+4,3*(F14/($J$4*0.6))+1)) -> 4.875
A15: 22046076-2 | B15: DIEZ/MORENO/MAGDALENA ISABEL | C15: 2 | D15: 19 | E15: 7.5 | F15: =SUM(D15:E15) -> 26.5 | G15: =IF(IF(F15>=$J$4*0.6,3*(((F15/$J$4)*100-60)/(100-60))+4,3*(F15/($J$4*0.6))+1)>7,7,IF(F15>=$J$4*0.6,3*(((F15/$J$4)*100-60)/(100-60))+4,3*(F15/($J$4*0.6))+1)) -> 3.2083333
A16: 21557420-2 | B16: ENCINA/DONOSO/FLORENCIA ALMENDRA | C16: 1 | D16: 14 | E16: 9 | F16: =SUM(D16:E16) -> 23 | G16: =IF(IF(F16>=$J$4*0.6,3*(((F16/$J$4)*100-60)/(100-60))+4,3*(F16/($J$4*0.6))+1)>7,7,IF(F16>=$J$4*0.6,3*(((F16/$J$4)*100-60)/(100-60))+4,3*(F16/($J$4*0.6))+1)) -> 2.9166667
... A24: 21905344-4 | B24: GORDON/GARCIA/MARIA JESUS | C24: 1 | D24: 17 | E24: 9 | F24: =SUM(D24:E24) -> 26 | G24: =IF(IF(F24>=$J$4*0.6,3*(((F24/$J$4)*100-60)/(100-60))+4,3*(F24/($J$4*0.6))+1)>7,7,IF(F24>=$J$4*0.6,3*(((F24/$J$4)*100-60)/(100-60))+4,3*(F24/($J$4*0.6))+1)) -> 3.1666667
A25: 21865263-8 | B25: HENRIQUEZ/NAWRATH/KALA | C25: 2 | G25: 3.6
A26: 21816695-4 | B26: HERRERA/PADILLA/LAURA ISABEL | C26: 2 | D26: 23 | E26: 7 | F26: =SUM(D26:E26) -> 30 | G26: =IF(IF(F26>=$J$4*0.6,3*(((F26/$J$4)*100-60)/(100-60))+4,3*(F26/($J$4*0.6))+1)>7,7,IF(F26>=$J$4*0.6,3*(((F26/$J$4)*100-60)/(100-60))+4,3*(F26/($J$4*0.6))+1)) -> 3.5
A27: 22011859-2 | B27: HOWARD/PEREZ/CRISTOBAL ANDRES | C27: 2 | D27: 19 | E27: 12 | F27: =SUM(D27:E27) -> 31 | G27: =IF(IF(F27>=$J$4*0.6,3*(((F27/$J$4)*100-60)/(100-60))+4,3*(F27/($J$4*0.6))+1)>7,7,IF(F27>=$J$4*0.6,3*(((F27/$J$4)*100-60)/(100-60))+4,3*(F27/($J$4*0.6))+1)) -> 3.5833333
A28: 21624852-K | B28: IZQUIERDO/MONTES/RAFAEL IGNACIO | C28: 2 | D28: 15 | E28: 8 | F28: =SUM(D28:E28) -> 23 | G28: =IF(IF(F28>=$J$4*0.6,3*(((F28/$J$4)*100-60)/(100-60))+4,3*(F28/($J$4*0.6))+1)>7,7,IF(F28>=$J$4*0.6,3*(((F28/$J$4)*100-60)/(100-60))+4,3*(F28/($J$4*0.6))+1)) -> 2.9166667
A29: 21845775-4 | B29: JIMENEZ/ANDREU/VICTORIA PAZ | C29: 1 | D29: 33 | E29: 12.5 | F29: =SUM(D29:E29) -> 45.5 | G29: =IF(IF(F29>=$J$4*0.6,3*(((F29/$J$4)*100-60)/(100-60))+4,3*(F29/($J$4*0.6))+1)>7,7,IF(F29>=$J$4*0.6,3*(((F29/$J$4)*100-60)/(100-60))+4,3*(F29/($J$4*0.6))+1)) -> 5.1875
A30: 21678194-5 | B30: JULLIAN/EYZAGUIRRE/BARBARA | C30: 2 | D30: 29 | E30: 17 | F30: =SUM(D30:E30) -> 46 | G30: =IF(IF(F30>=$J$4*0.6,3*(((F30/$J$4)*100-60)/(100-60))+4,3*(F30/($J$4*0.6))+1)>7,7,IF(F30>=$J$4*0.6,3*(((F30/$J$4)*100-60)/(100-60))+4,3*(F30/($J$4*0.6))+1)) -> 5.25
A31: 21853700-6 | B31: LATORRE/AHUMADA/JOSEFA | C31: 2 | D31: 27 | E31: 12 | F31: =SUM(D31:E31) -> 39 | G31: =IF(IF(F31>=$J$4*0.6,3*(((F31/$J$4)*100-60)/(100-60))+4,3*(F31/($J$4*0.6))+1)>7,7,IF(F31>=$J$4*0.6,3*(((F31/$J$4)*100-60)/(100-60))+4,3*(F31/($J$4*0.6))+1)) -> 4.375
A32: 21527204-4 | B32: LAVIN/VALLEJOS/IGNACIA MARIA | C32: 2 | D32: 20 | E32: 9.5 | F32: =SUM(D32:E32) -> 29.5 | G32: =IF(IF(F32>=$J$4*0.6,3*(((F32/$J$4)*100-60)/(100-60))+4,3*(F32/($J$4*0.6))+1)>7,7,IF(F32>=$J$4*0.6,3*(((F32/$J$4)*100-60)/(100-60))+4,3*(F32/($J$4*0.6))+1)) -> 3.4583333
A33: 21923918-1 | B33: LIM/ARIAS/FLORENCIA AUGUSTA | C33: 2 | D33: 22 | E33: 10 | F33: =SUM(D33:E33) -> 32 | G33: =IF(IF(F33>=$J$4*0.6,3*(((F33/$J$4)*100-60)/(100-60))+4,3*(F33/($J$4*0.6))+1)>7,7,IF(F33>=$J$4*0.6,3*(((F33/$J$4)*100-60)/(100-60))+4,3*(F33/($J$4*0.6))+1)) -> 3.6666667
A34: 21611454-K | B34: LOPEZ/RETAMAL/JOSEFINA ESPERANZA | C34: 1 | D34: 27 | E34: 11 | F34: =SUM(D34:E34) -> 38 | G34: =IF(IF(F34>=$J$4*0.6,3*(((F34/$J$4)*100-60)/(100-60))+4,3*(F34/($J$4*0.6))+1)>7,7,IF(F34>=$J$4*0.6,3*(((F34/$J$4)*100-60)/(100-60))+4,3*(F34/($J$4*0.6))+1)) -> 4.25
A35: 21713214-2 | B35: LOPEZ/THAYER/GABRIEL AMAI | C35: 1 | D35: 35 | E35: 18 | F35: =SUM(D35:E35) -> 53 | G35: =IF(IF(F35>=$J$4*0.6,3*(((F35/$J$4)*100-60)/(100-60))+4,3*(F35/($J$4*0.6))+1)>7,7,IF(F35>=$J$4*0.6,3*(((F35/$J$4)*100-60)/(100-60))+4,3*(F35/($J$4*0.6))+1)) -> 6.125
A36: 21760460-5 | B36: MALDONADO/ARCE/SOFIA ANTONIA | C36: 1 | D36: 21 | E36: 7 | F36: =SUM(D36:E36) -> 28 | G36: =IF(IF(F36>=$J$4*0.6,3*(((F36/$J$4)*100-60)/(100-60))+4,3*(F36/($J$4*0.6))+1)>7,7,IF(F36>=$J$4*0.6,3*(((F36/$J$4)*100-60)/(100-60))+4,3*(F36/($J$4*0.6))+1)) -> 3.3333333
A37: 21833415-6 | B37: MARTINEZ/AGUILAR/SEBASTIAN PABLO | C37: 1 | D37: 28 | E37: 10 | F37: =SUM(D37:E37) -> 38 | G37: =IF(IF(F37>=$J$4*0.6,3*(((F37/$J$4)*100-60)/(100-60))+4,3*(F37/($J$4*0.6))+1)>7,7,IF(F37>=$J$4*0.6,3*(((F37/$J$4)*100-60)/(100-60))+4,3*(F37/($J$4*0.6))+1)) -> 4.25
... A56: 26418342-1 | B56: RAMOS/NIÑO/ADRIAN MAURICIO | C56: 1 | D56: 25 | E56: 5.5 | F56: =SUM(D56:E56) -> 30.5 | G56: =IF(IF(F56>=$J$4*0.6,3*(((F56/$J$4)*100-60)/(100-60))+4,3*(F56/($J$4*0.6))+1)>7,7,IF(F56>=$J$4*0.6,3*(((F56/$J$4)*100-60)/(100-60))+4,3*(F56/($J$4*0.6))+1)) -> 3.5416667
A57: 21323382-3 | B57: RATTO/ESCOBAR/JAVIER BENJAMIN | C57: 1 | G57: 2.1
A58: 21182328-3 | B58: REBOLLEDO/TOMICIC/AGUSTINA ELVIRA | C58: 1 | D58: 14 | E58: 8 | F58: =SUM(D58:E58) -> 22 | G58: =IF(IF(F58>=$J$4*0.6,3*(((F58/$J$4)*100-60)/(100-60))+4,3*(F58/($J$4*0.6))+1)>7,7,IF(F58>=$J$4*0.6,3*(((F58/$J$4)*100-60)/(100-60))+4,3*(F58/($J$4*0.6))+1)) -> 2.8333333
A59: 21763037-1 | B59: ROA/RUBILAR/FRANCISCO IGNACIO | C59: 1 | D59: 37 | E59: 21.5 | F59: =SUM(D59:E59) -> 58.5 | G59: =IF(IF(F59>=$J$4*0.6,3*(((F59/$J$4)*100-60)/(100-60))+4,3*(F59/($J$4*0.6))+1)>7,7,IF(F59>=$J$4*0.6,3*(((F59/$J$4)*100-60)/(100-60))+4,3*(F59/($J$4*0.6))+1)) -> 6.8125
A60: 21879193-K | B60: ROBESON/CARVALLO/MARIA | C60: 2 | D60: 14 | E60: 9 | F60: =SUM(D60:E60) -> 23 | G60: =IF(IF(F60>=$J$4*0.6,3*(((F60/$J$4)*100-60)/(100-60))+4,3*(F60/($J$4*0.6))+1)>7,7,IF(F60>=$J$4*0.6,3*(((F60/$J$4)*100-60)/(100-60))+4,3*(F60/($J$4*0.6))+1)) -> 2.9166667
A61: 21495306-4 | B61: RODRIGUEZ/CARREÑO/ANTONIA SOFIA | C61: 2 | D61: 11 | E61: 6.5 | F61: =SUM(D61:E61) -> 17.5 | G61: =IF(IF(F61>=$J$4*0.6,3*(((F61/$J$4)*100-60)/(100-60))+4,3*(F61/($J$4*0.6))+1)>7,7,IF(F61>=$J$4*0.6,3*(((F61/$J$4)*100-60)/(100-60))+4,3*(F61/($J$4*0.6))+1)) -> 2.4583333
A62: 21720165-9 | B62: ROJAS/MASSARDO/OSVALDO IGNACIO | C62: 2 | D62: 26 | E62: 12 | F62: =SUM(D62:E62) -> 38 | G62: =IF(IF(F62>=$J$4*0.6,3*(((F62/$J$4)*100-60)/(100-60))+4,3*(F62/($J$4*0.6))+1)>7,7,IF(F62>=$J$4*0.6,3*(((F62/$J$4)*100-60)/(100-60))+4,3*(F62/($J$4*0.6))+1)) -> 4.25
A63: 21182660-6 | B63: SAHADY/MOLINA/FERNANDO JAVIER | C63: 1 | D63: 16 | E63: 11 | F63: =SUM(D63:E63) -> 27 | G63: =IF(IF(F63>=$J$4*0.6,3*(((F63/$J$4)*100-60)/(100-60))+4,3*(F63/($J$4*0.6))+1)>7,7,IF(F63>=$J$4*0.6,3*(((F63/$J$4)*100-60)/(100-60))+4,3*(F63/($J$4*0.6))+1)) -> 3.25
A64: 21575650-5 | B64: SANTELICES/SAINZ/TOMAS FELIPE | C64: 2 | D64: 19 | E64: 8.5 | F64: =SUM(D64:E64) -> 27.5 | G64: =IF(IF(F64>=$J$4*0.6,3*(((F64/$J$4)*100-60)/(100-60))+4,3*(F64/($J$4*0.6))+1)>7,7,IF(F64>=$J$4*0.6,3*(((F64/$J$4)*100-60)/(100-60))+4,3*(F64/($J$4*0.6))+1)) -> 3.2916667
A65: 21430916-5 | B65: SCHNEIDER/RUIZ DE VIÑASPRE/CATALINA URSULA | C65: 1 | D65: 23 | E65: 12 | F65: =SUM(D65:E65) -> 35 | G65: =IF(IF(F65>=$J$4*0.6,3*(((F65/$J$4)*100-60)/(100-60))+4,3*(F65/($J$4*0.6))+1)>7,7,IF(F65>=$J$4*0.6,3*(((F65/$J$4)*100-60)/(100-60))+4,3*(F65/($J$4*0.6))+1)) -> 3.9166667
...

Sheet Controles
A1: RUT | B1: IDENTIFICACIÓN | C1: SECCIÓN | D1: C1 | E1: C2 | F1: C3 | G1: C4 | H1: C5 | I1: C6 | J1: C7 | K1: C8 | L1: C9 | M1: C10 | N1: PROMEDIO
B2: SECCIÓN 1 | D2: 45881 | E2: 45895 | F2: 45902 | G2: 45909 | H2: 45916 | I2: 45937 | J2: 45944 | K2: 45951 | L2: 45958 | M2: 45965
A3: 21222465-0 | B3: BASULTO/PEREIRA/VICENTE JOSE | C3: 1 | D3: 6.4 | E3: 4 | F3: 2 | H3: 3 | I3: 5 | J3: 6 | K3: 3 | L3: 4 | M3: 3 | N3: =(SUM(D3:M3)-MIN(D3:M3))/(COUNT(D3:M3)-1) -> 4.3
A4: 21952179-0 | B4: BERGUÑO/ALVAREZ/ISABELA PAZ | C4: 1 | D4: 7 | E4: 7 | F4: 6 | H4: 5.5 | I4: 6 | J4: 3.5 | K4: 6 | L4: 4 | M4: 6.5 | N4: =(SUM(D4:M4)-MIN(D4:M4))/(COUNT(D4:M4)-1) -> 6
A5: 21879129-8 | B5: BOLOGNESI/AGUADO/LUCIANA | C5: 1 | D5: 4.6 | E5: 6 | F5: 4 | H5: 2.5 | I5: 3 | J5: 7 | K5: 1 | L5: 1 | M5: 4.5 | N5: =(SUM(D5:M5)-MIN(D5:M5))/(COUNT(D5:M5)-1) -> 4.075
A6: 21557420-2 | B6: ENCINA/DONOSO/FLORENCIA ALMENDRA | C6: 1 | D6: 7 | E6: 2 | F6: 5 | H6: 2.5 | I6: 1 | J6: J | K6: 4 | L6: 6 | M6: J | N6: =(SUM(D6:M6)-MIN(D6:M6))/(COUNT(D6:M6)-1) -> 4.4166667
A7: 21840694-7 | B7: ESCOBAR/QUEZADA/VALENTINA PAZ | C7: 1 | D7: 7 | E7: 7 | F7: 7 | H7: 2.5 | I7: 7 | J7: 6.5 | K7: 1 | L7: J | M7: 3 | N7: =(SUM(D7:M7)-MIN(D7:M7))/(COUNT(D7:M7)-1) -> 5.7142857
A8: 21268200-4 | B8: GARCIA-HUIDOBRO/FUENZALIDA/SANTIAGO TOMAS | C8: 1 | D8: 5.8 | E8: 7 | F8: 7 | H8: 2 | I8: 3 | J8: J | K8: 1 | L8: 7 | M8: 7 | N8: =(SUM(D8:M8)-MIN(D8:M8))/(COUNT(D8:M8)-1) -> 5.5428571
A9: 21833671-K | B9: GARCIA/OLIVA/JAVIERA IGNACIA | C9: 1 | D9: 7 | E9: 5.5 | F9: 4 | H9: 2.5 | I9: 4 | J9: 7 | K9: 4 | L9: 7 | M9: 5 | N9: =(SUM(D9:M9)-MIN(D9:M9))/(COUNT(D9:M9)-1)+0.1 -> 5.5375
A10: 22082471-3 | B10: GIESLER/SOTO/EMILY THERESA | C10: 1 | D10: 1.6 | E10: 7 | F10: 7 | H10: 7 | I10: 7 | J10: 7 | K10: 7 | L10: 7 | M10: 7 | N10: =(SUM(D10:M10)-MIN(D10:M10))/(COUNT(D10:M10)-1) -> 7
A11: 21769435-3 | B11: GOMEZ/GONZALEZ/DOMINGA ANTONIA | C11: 1 | D11: 6.4 | E11: 7 | F11: 6 | H11: J | I11: 2 | J11: 7 | K11: J | L11: 1 | M11: 4 | N11: =(SUM(D11:M11)-MIN(D11:M11))/(COUNT(D11:M11)-1) -> 5.4
A12: 21678275-5 | B12: GONZALEZ/ALCERRECA/SOFIA TEODORA | C12: 1 | D12: 1 | E12: 1 | F12: 3 | H12: 2.5 | I12: 1 | J12: 5.5 | K12: 2 | L12: 1 | M12: 3 | N12: =(SUM(D12:M12)-MIN(D12:M12))/(COUNT(D12:M12)-1) -> 2.375
A13: 21905344-4 | B13: GORDON/GARCIA/MARIA JESUS | C13: 1 | D13: 5.5 | E13: 5.5 | F13: 2 | H13: 4 | I13: 2 | J13: 3 | K13: 1.5 | L13: 1 | M13: 3.5 | N13: =(SUM(D13:M13)-MIN(D13:M13))/(COUNT(D13:M13)-1) -> 3.375
A14: 21845775-4 | B14: JIMENEZ/ANDREU/VICTORIA PAZ | C14: 1 | D14: 5.8 | E14: 7 | F14: 6 | H14: 7 | I14: 7 | J14: 7 | K14: 7 | L14: 6 | M14: 6 | N14: =(SUM(D14:M14)-MIN(D14:M14))/(COUNT(D14:M14)-1) -> 6.625
A15: 21611454-K | B15: LOPEZ/RETAMAL/JOSEFINA ESPERANZA | C15: 1 | D15: 4.6 | E15: 5 | F15: 5 | H15: 3 | I15: 3 | J15: 7 | K15: 6 | L15: 7 | M15: 2 | N15: =(SUM(D15:M15)-MIN(D15:M15))/(COUNT(D15:M15)-1) -> 5.075
A16: 21713214-2 | B16: LOPEZ/THAYER/GABRIEL AMAI | C16: 1 | D16: 7 | E16: 5.5 | F16: 7 | H16: 6 | I16: 7 | J16: 7 | K16: 7 | L16: 7 | M16: 1 | N16: =(SUM(D16:M16)-MIN(D16:M16))/(COUNT(D16:M16)-1) -> 6.6875
A17: 21760460-5 | B17: MALDONADO/ARCE/SOFIA ANTONIA | C17: 1 | D17: 7 | E17: 6 | F17: 5 | H17: 2 | I17: 2 | J17: 7 | K17: 1 | L17: 1 | M17: 7 | N17: =(SUM(D17:M17)-MIN(D17:M17))/(COUNT(D17:M17)-1) -> 4.625
A18: 21833415-6 | B18: MARTINEZ/AGUILAR/SEBASTIAN PABLO | C18: 1 | D18: 1.6 | E18: 3.5 | F18: 4 | H18: 1 | I18: 5 | J18: 1 | K18: 3 | L18: 1 | M18: 1 | N18: =(SUM(D18:M18)-MIN(D18:M18))/(COUNT(D18:M18)-1) -> 2.5125
A19: 21940672-K | B19: MATURANA/FUENTES/ALEX DANIEL | C19: 1 | D19: 7 | E19: 7 | F19: 2 | H19: 3 | I19: 4 | J19: 7 | K19: 2.5 | L19: 7 | M19: 6.5 | N19: =(SUM(D19:M19)-MIN(D19:M19))/(COUNT(D19:M19)-1)+0.1 -> 5.6
A20: 21503007-5 | B20: MIRANDA/MITCHEL/PABLO SEBASTIAN | C20: 1 | D20: 1 | E20: 4.5 | F20: 2 | H20: 1 | I20: 1 | J20: 7 | K20: 3.5 | L20: 7 | M20: 2 | N20: =(SUM(D20:M20)-MIN(D20:M20))/(COUNT(D20:M20)-1) -> 3.5
A21: 21908752-7 | B21: MORAGA/CASTRO/CRISTIAN EDUARDO | C21: 1 | D21: 7 | E21: 6 | F21: 3 | H21: 5.5 | I21: 7 | J21: 7 | K21: 7 | L21: 4.5 | M21: 7 | N21: =(SUM(D21:M21)-MIN(D21:M21))/(COUNT(D21:M21)-1)+0.1 -> 6.475
A22: 21634848-6 | B22: MORALES/KULM/MARTINA ANDREA | C22: 1 | D22: 7 | E22: 5 | F22: 7 | H22: 5 | I22: 7 | J22: 7 | K22: 7 | L22: 7 | M22: 2 | N22: =(SUM(D22:M22)-MIN(D22:M22))/(COUNT(D22:M22)-1) -> 6.5
A23: 21182124-8 | B23: MOYA/CERDA/JAVIERA PAZ | C23: 1 | D23: 1 | E23: 1 | F23: J | H23: 1 | I23: 1 | J23: 1 | K23: 1 | L23: 1 | M23: 1 | N23: =(SUM(D23:M23)-MIN(D23:M23))/(COUNT(D23:M23)-1) -> 1
A24: 20807332-K | B24: MUNRO/LASO/ISIDORA . | C24: 1 | D24: 5.8 | E24: 6 | F24: 7 | H24: 4 | I24: 5 | J24: 7 | K24: 4 | L24: 1 | M24: 2 | N24: =(SUM(D24:M24)-MIN(D24:M24))/(COUNT(D24:M24)-1) -> 5.1
A25: 22144401-9 | B25: NUÑEZ/ROMERO/VICENTE ANDRES | C25: 1 | D25: 7 | E25: 7 | F25: 7 | H25: 5.5 | I25: 5 | J25: 5.5 | K25: 5.5 | L25: 7 | M25: 5.5 | N25: =(SUM(D25:M25)-MIN(D25:M25))/(COUNT(D25:M25)-1) -> 6.25
A26: 21716504-0 | B26: ORELLANA/CACHICH/ALBERTO ISA | C26: 1 | D26: 6.4 | E26: 7 | F26: 6 | H26: 6.5 | I26: 7 | J26: 7 | K26: 6.5 | L26: 7 | M26: 7 | N26: =(SUM(D26:M26)-MIN(D26:M26))/(COUNT(D26:M26)-1) -> 6.8
A27: 21183322-K | B27: PASCUAL /VARAS/CRISTINA ANDREA | C27: 1 | D27: 4 | E27: 5 | F27: 4 | H27: 1.5 | I27: 1 | J27: 7 | K27: 1 | L27: 1 | M27: 4.5 | N27: =(SUM(D27:M27)-MIN(D27:M27))/(COUNT(D27:M27)-1) -> 3.5
A28: 21183019-0 | B28: PEREZ/ESPINOZA/IGNACIA JOSEFINA | C28: 1 | D28: 6.4 | E28: 3 | F28: 7 | H28: J | I28: J | J28: J | K28: J | L28: J | M28: 2 | N28: =(SUM(D28:M28)-MIN(D28:M28))/(COUNT(D28:M28)-1) -> 5.4666667
A29: 21253286-K | B29: PICO/CASTRO/SIMONE PAZ | C29: 1 | D29: 4.6 | E29: 7 | F29: 3 | H29: 5 | I29: 5 | J29: 7 | K29: 3.5 | L29: 4 | M29: 2 | N29: =(SUM(D29:M29)-MIN(D29:M29))/(COUNT(D29:M29)-1) -> 4.8875
A30: 26418342-1 | B30: RAMOS/NIÑO/ADRIAN MAURICIO | C30: 1 | D30: 6.4 | E30: 4 | F30: 5 | H30: 2.5 | I30: J | J30: J | K30: 2 | L30: 5.5 | M30: 2 | N30: =(SUM(D30:M30)-MIN(D30:M30))/(COUNT(D30:M30)-1) -> 4.2333333
A31: 21323382-3 | B31: RATTO/ESCOBAR/JAVIER BENJAMIN | C31: 1 | D31: 4 | E31: 7 | F31: 5 | H31: 2.5 | I31: 1 | J31: 7 | K31: 7 | L31: 4 | M31: 2 | N31: =(SUM(D31:M31)-MIN(D31:M31))/(COUNT(D31:M31)-1)+0.1 -> 4.9125
A32: 21182328-3 | B32: REBOLLEDO/TOMICIC/AGUSTINA ELVIRA | C32: 1 | D32: 7 | E32: 4 | F32: 4 | H32: 2.5 | I32: 3 | J32: 6 | K32: 1 | L32: 7 | M32: 5.5 | N32: =(SUM(D32:M32)-MIN(D32:M32))/(COUNT(D32:M32)-1) -> 4.875
A33: 21763037-1 | B33: ROA/RUBILAR/FRANCISCO IGNACIO | C33: 1 | D33: 4.6 | E33: 7 | F33: 7 | H33: 7 | I33: 7 | J33: 7 | K33: 7 | L33: 6 | M33: 6.5 | N33: =(SUM(D33:M33)-MIN(D33:M33))/(COUNT(D33:M33)-1) -> 6.8125
A34: 21182660-6 | B34: SAHADY/MOLINA/FERNANDO JAVIER | C34: 1 | D34: 3.4 | E34: 4 | F34: 2 | H34: 3.5 | I34: 1 | J34: 3 | K34: 6 | L34: 1 | M34: 3.5 | N34: =(SUM(D34:M34)-MIN(D34:M34))/(COUNT(D34:M34)-1) -> 3.3
A35: 21430916-5 | B35: SCHNEIDER/RUIZ DE VIÑASPRE/CATALINA URSULA | C35: 1 | D35: 1.6 | E35: 2 | F35: 2 | H35: 2.5 | I35: 7 | J35: 7 | K35: 5.5 | L35: 1 | M35: 1 | N35: =(SUM(D35:M35)-MIN(D35:M35))/(COUNT(D35:M35)-1) -> 3.575
A36: 21748601-7 | B36: SCHURCH/ZEINER/ALINE | C36: 1 | D36: 2.2 | E36: 6 | F36: 7 | H36: 5.5 | I36: 7 | J36: 4 | K36: 3.5 | L36: 7 | M36: 7 | N36: =(SUM(D36:M36)-MIN(D36:M36))/(COUNT(D36:M36)-1) -> 5.875
A37: 21478962-0 | B37: SEPULVEDA/HERNANDEZ/LAURA ALEJANDRA | C37: 1 | D37: 3.4 | E37: 1 | F37: 4 | H37: J | I37: 1 | J37: 1 | K37: 1 | L37: 1 | M37: 1 | N37: =(SUM(D37:M37)-MIN(D37:M37))/(COUNT(D37:M37)-1) -> 1.7714286
A38: 21885336-6 | B38: SIMONET/BUSTOS/MARTINA SOFIA | C38: 1 | D38: 3.4 | E38: 7 | F38: 5 | H38: 7 | I38: 3 | J38: 6 | K38: 1 | L38: 4 | M38: 4.5 | N38: =(SUM(D38:M38)-MIN(D38:M38))/(COUNT(D38:M38)-1) -> 4.9875
A39: 21450814-1 | B39: SISTEK/CHELLEW/BENITO | C39: 1 | D39: 7 | E39: 2.5 | F39: 5 | H39: 1 | I39: 1 | J39: 7 | K39: 7 | L39: 1 | M39: 4.5 | N39: =(SUM(D39:M39)-MIN(D39:M39))/(COUNT(D39:M39)-1) -> 4.375
A40: 21836303-2 | B40: SOTO/LOBOS/RENATA IGNACIA | C40: 1 | D40: 2.8 | E40: 3 | F40: 2 | H40: 1 | I40: 3 | J40: 7 | K40: 5 | L40: 1 | M40: 1 | N40: =(SUM(D40:M40)-MIN(D40:M40))/(COUNT(D40:M40)-1) -> 3.1
...

Sheet Tareas grupales
A1: RUT | B1: IDENTIFICACIÓN | C1: GRUPO | D1: SECCION | E1: TAREA 1 | F1: TAREA 2 | G1: TAREA 3 | H1: TAREA 4 | I1: TAREA 5 | J1: PROMEDIO BRUTO | K1: EV. PAR | L1: CASTIGO | M1: PROMEDIO AJUSTADO
A2: 21222465-0 | B2: BASULTO/PEREIRA/VICENTE JOSE | C2: =VLOOKUP(B2, 'Grupos 1'!$B:$C, 2, FALSE) -> 6 | D2: 1 | E2: 6.7 | F2: 5.4 | G2: 3.7 | H2: 5.1 | I2: 4.5 | J2: =AVERAGE(E2:I2) -> 5.08 | K2: 6.8 | L2: 1 | M2: 5
A3: 21952179-0 | B3: BERGUÑO/ALVAREZ/ISABELA PAZ | C3: =VLOOKUP(B3, 'Grupos 1'!$B:$C, 2, FALSE) -> 10 | D3: 1 | E3: 6.1 | F3: 4.2 | G3: 5.8 | H3: 6.4 | I3: 3.5 | J3: =AVERAGE(E3:I3) -> 5.2 | K3: 7 | L3: 1 | M3: 5.8
A4: 21879129-8 | B4: BOLOGNESI/AGUADO/LUCIANA | C4: =VLOOKUP(B4, 'Grupos 1'!$B:$C, 2, FALSE) -> 8 | D4: 1 | E4: 6.4 | F4: 4.8 | G4: 3.9 | H4: 5.1 | I4: 3.3 | J4: =AVERAGE(E4:I4) -> 4.7 | K4: 6.8 | L4: 1 | M4: 5
A5: 21557420-2 | B5: ENCINA/DONOSO/FLORENCIA ALMENDRA | C5: =VLOOKUP(B5, 'Grupos 1'!$B:$C, 2, FALSE) -> 7 | D5: 1 | E5: 6.1 | F5: 3.9 | G5: 5.8 | H5: 4.2 | I5: 5.4 | J5: =AVERAGE(E5:I5) -> 5.08 | K5: 5.1 | L5: 1 | M5: 4.4
A6: 21840694-7 | B6: ESCOBAR/QUEZADA/VALENTINA PAZ | C6: =VLOOKUP(B6, 'Grupos 1'!$B:$C, 2, FALSE) -> 4 | D6: 1 | E6: 7 | F6: 7 | G6: 6.4 | H6: 6.4 | I6: 5.1 | J6: =AVERAGE(E6:I6) -> 6.38 | K6: 7 | L6: 0.98 | M6: 6.3
A7: 21268200-4 | B7: GARCIA-HUIDOBRO/FUENZALIDA/SANTIAGO TOMAS | C7: =VLOOKUP(B7, 'Grupos 1'!$B:$C, 2, FALSE) -> 5 | D7: 1 | E7: 6.4 | F7: 5.4 | G7: 6.4 | H7: 5.4 | I7: 4.5 | J7: =AVERAGE(E7:I7) -> 5.62 | K7: 7 | L7: 1 | M7: 5.8
A8: 21833671-K | B8: GARCIA/OLIVA/JAVIERA IGNACIA | C8: =VLOOKUP(B8, 'Grupos 1'!$B:$C, 2, FALSE) -> 3 | D8: 1 | E8: 6.4 | F8: 7 | G8: 5.8 | H8: 6.4 | I8: 2.9 | J8: =AVERAGE(E8:I8) -> 5.7 | K8: 6.5 | L8: 1 | M8: 5.5
A9: 22082471-3 | B9: GIESLER/SOTO/EMILY THERESA | C9: =VLOOKUP(B9, 'Grupos 1'!$B:$C, 2, FALSE) -> 2 | D9: 1 | E9: 7 | F9: 6.4 | G9: 5.1 | H9: 7 | I9: 4.8 | J9: =AVERAGE(E9:I9) -> 6.06 | K9: 6.4 | L9: 1 | M9: 6.2
A10: 21769435-3 | B10: GOMEZ/GONZALEZ/DOMINGA ANTONIA | C10: =VLOOKUP(B10, 'Grupos 1'!$B:$C, 2, FALSE) -> 9 | D10: 1 | E10: 7 | F10: 3.9 | G10: 3.9 | H10: 5.8 | I10: 3.9 | J10: =AVERAGE(E10:I10) -> 4.9 | K10: 4.2 | L10: 1 | M10: 3.8
A11: 21678275-5 | B11: GONZALEZ/ALCERRECA/SOFIA TEODORA | C11: =VLOOKUP(B11, 'Grupos 1'!$B:$C, 2, FALSE) -> 4 | D11: 1 | E11: 7 | F11: 7 | G11: 6.4 | H11: 6.4 | I11: 5.1 | J11: =AVERAGE(E11:I11) -> 6.38 | K11: 6.9 | L11: 1 | M11: 6.3
A12: 21905344-4 | B12: GORDON/GARCIA/MARIA JESUS | C12: =VLOOKUP(B12, 'Grupos 1'!$B:$C, 2, FALSE) -> 4 | D12: 1 | E12: 7 | F12: 7 | G12: 6.4 | H12: 6.4 | I12: 5.1 | J12: =AVERAGE(E12:I12) -> 6.38 | K12: 7 | L12: 1 | M12: 6.4
A13: 21845775-4 | B13: JIMENEZ/ANDREU/VICTORIA PAZ | C13: =VLOOKUP(B13, 'Grupos 1'!$B:$C, 2, FALSE) -> 5 | D13: 1 | E13: 6.4 | F13: 5.4 | G13: 6.4 | H13: 5.4 | I13: 4.5 | J13: =AVERAGE(E13:I13) -> 5.62 | K13: 7 | L13: 1 | M13: 5.8
... A44: 21822834-8 | B44: VEGA/SUAREZ/PAZ ANTONIA | C44: =VLOOKUP(B44, 'Grupos 1'!$B:$C, 2, FALSE) -> 9 | D44: 1 | E44: 7 | F44: 3.9 | G44: 3.9 | H44: 5.8 | I44: 3.9 | J44: =AVERAGE(E44:I44) -> 4.9 | K44: 5 | L44: 1 | M44: 4.6
A45: 21043404-6 | B45: ANGELLOTTI/MARTINEZ/RAIMUNDO TOMAS | C45: =VLOOKUP(B45, 'Grupos 2'!B:C, 2, FALSE) -> 15 | D45: 2 | E45: 6.4 | F45: 5.4 | G45: 4.5 | H45: 4.8 | I45: 3.3 | J45: =AVERAGE(E45:I45) -> 4.88 | K45: 7 | L45: 1 | M45: 4.9
A46: 21708911-5 | B46: BENITEZ/RAMIREZ/JOAQUIN IGNACIO | C46: =VLOOKUP(B46, 'Grupos 2'!B:C, 2, FALSE) -> 19 | D46: 2 | E46: 6.1 | F46: 4.8 | G46: 3.9 | H46: 5.1 | I46: 2.9 | J46: =AVERAGE(E46:I46) -> 4.56 | K46: 6.6 | L46: 0.9 | M46: 4
A47: 21792244-5 | B47: BIZE/HENRIQUEZ/CRISTOBAL IGNACIO | C47: =VLOOKUP(B47, 'Grupos 2'!B:C, 2, FALSE) -> 16 | D47: 2 | E47: 7 | F47: 5.4 | G47: 5.8 | H47: 4.8 | I47: 2 | J47: =AVERAGE(E47:I47) -> 5 | K47: 7 | L47: 1 | M47: 5
A48: 21566004-4 | B48: BRIONES/MEZA/DIEGO ANTONIO | C48: =VLOOKUP(B48, 'Grupos 2'!B:C, 2, FALSE) -> 19 | D48: 2 | E48: 6.1 | F48: 4.8 | G48: 3.9 | H48: 5.1 | I48: 2.9 | J48: =AVERAGE(E48:I48) -> 4.56 | K48: 7 | L48: 1 | M48: 4.7
A49: 21896364-1 | B49: BUSTAMANTE/CARTAGENA/VANESSA EMILIA | C49: =VLOOKUP(B49, 'Grupos 2'!B:C, 2, FALSE) -> 17 | D49: 2 | E49: 7 | F49: 4.8 | G49: 5.8 | H49: 5.1 | I49: 3.1 | J49: =AVERAGE(E49:I49) -> 5.16 | K49: 6.8 | L49: 1 | M49: 5.2
A50: 21149692-4 | B50: CAÑETE/OCAMPO/ROSARIO PAZ | C50: =VLOOKUP(B50, 'Grupos 2'!B:C, 2, FALSE) -> 11 | D50: 2 | E50: 7 | F50: 6.1 | G50: 4.5 | H50: 6.4 | I50: 1.6 | J50: =AVERAGE(E50:I50) -> 5.12 | K50: 4.5 | L50: 1 | M50: 3.8
A51: 22030122-2 | B51: CARO/TRONCOSO/MARTINA LORETO | C51: =VLOOKUP(B51, 'Grupos 2'!B:C, 2, FALSE) -> 11 | D51: 2 | E51: 7 | F51: 6.1 | G51: 4.5 | H51: 6.4 | I51: 1.6 | J51: =AVERAGE(E51:I51) -> 5.12 | K51: 7 | L51: 1 | M51: 5.9
A52: 21840696-3 | B52: CHADE/ARIAS/MARIO EDUARDO | C52: =VLOOKUP(B52, 'Grupos 2'!B:C, 2, FALSE) -> 13 | D52: 2 | E52: 6.4 | F52: 4.8 | G52: 4.5 | H52: 4.8 | I52: 2 | J52: =AVERAGE(E52:I52) -> 4.5 | K52: 7 | L52: 1 | M52: 4.5
A53: 21559935-3 | B53: DIAZ/ALLAIN/PABLO ANDRES | C53: =VLOOKUP(B53, 'Grupos 2'!B:C, 2, FALSE) -> 18 | D53: 2 | E53: 4.8 | F53: 3.1 | G53: 3.5 | H53: 6.4 | I53: 2.3 | J53: =AVERAGE(E53:I53) -> 4.02 | K53: 7 | L53: 1 | M53: 4
A54: 21988754-K | B54: DIAZ/FORNI/FERNANDA JESUS | C54: =VLOOKUP(B54, 'Grupos 2'!B:C, 2, FALSE) -> 15 | D54: 2 | E54: 6.4 | F54: 5.4 | G54: 4.5 | H54: 4.8 | I54: 3.3 | J54: =AVERAGE(E54:I54) -> 4.88 | K54: 7 | L54: 1 | M54: 4.9
A55: 22046076-2 | B55: DIEZ/MORENO/MAGDALENA ISABEL | C55: =VLOOKUP(B55, 'Grupos 2'!B:C, 2, FALSE) -> 14 | D55: 2 | E55: 6.1 | F55: 5.8 | G55: 4.5 | H55: 4.8 | I55: 3.3 | J55: =AVERAGE(E55:I55) -> 4.9 | K55: 6.8 | L55: 1 | M55: 5
A56: 21893593-1 | B56: GARRIGA/ARGANDOÑA/BENJAMIN IAIR | C56: =VLOOKUP(B56, 'Grupos 2'!B:C, 2, FALSE) -> 12 | D56: 2 | E56: 6.7 | F56: 6.4 | G56: 4.5 | H56: 5.4 | I56: 2.3 | J56: =AVERAGE(E56:I56) -> 5.06 | K56: 3.7 | L56: 1 | M56: 3.4
... A81: 21717140-7 | B81: WOODYATT/ULRIKSEN/MARIA MARTINA | C81: =VLOOKUP(B81, 'Grupos 2'!B:C, 2, FALSE) -> 17 | D81: 2 | E81: 7 | F81: 4.8 | G81: 5.8 | H81: 5.1 | I81: 3.1 | J81: =AVERAGE(E81:I81) -> 5.16 | K81: 7 | L81: 1 | M81: 5.4

Sheet Examen
A1: RUT | B1: IDENTIFICACIÓN | C1: SECCIÓN | D1: ALTERNATIVAS | E1: DESARROLLO | F1: TOTAL | G1: NOTA
A2: 21043404-6 | B2: ANGELLOTTI/MARTINEZ/RAIMUNDO TOMAS | C2: 2 | I2: Puntaje ideal | J2: 60
A3: 21222465-0 | B3: BASULTO/PEREIRA/VICENTE JOSE | C3: 1 | D3: 17 | E3: 10.5 | F3: =SUM(D3:E3) -> 27.5 | G3: =IF(IF(F3>=$J$4*0.6,3*(((F3/$J$4)*100-60)/(100-60))+4,3*(F3/($J$4*0.6))+1)>7,7,IF(F3>=$J$4*0.6,3*(((F3/$J$4)*100-60)/(100-60))+4,3*(F3/($J$4*0.6))+1)) -> 3.4122807 | H3: 1 | I3: Puntaje real | J3: =MAX(F:F) -> 41.5
A4: 21708911-5 | B4: BENITEZ/RAMIREZ/JOAQUIN IGNACIO | C4: 2 | D4: 21 | E4: 12 | F4: =SUM(D4:E4) -> 33 | G4: =IF(IF(F4>=$J$4*0.6,3*(((F4/$J$4)*100-60)/(100-60))+4,3*(F4/($J$4*0.6))+1)>7,7,IF(F4>=$J$4*0.6,3*(((F4/$J$4)*100-60)/(100-60))+4,3*(F4/($J$4*0.6))+1)) -> 3.8947368 | H4: 1 | I4: Puntaje final | J4: 57
A5: 21952179-0 | B5: BERGUÑO/ALVAREZ/ISABELA PAZ | C5: 1
A6: 21792244-5 | B6: BIZE/HENRIQUEZ/CRISTOBAL IGNACIO | C6: 2 | D6: 15 | E6: 10 | F6: =SUM(D6:E6) -> 25 | G6: =IF(IF(F6>=$J$4*0.6,3*(((F6/$J$4)*100-60)/(100-60))+4,3*(F6/($J$4*0.6))+1)>7,7,IF(F6>=$J$4*0.6,3*(((F6/$J$4)*100-60)/(100-60))+4,3*(F6/($J$4*0.6))+1)) -> 3.1929825
A7: 21879129-8 | B7: BOLOGNESI/AGUADO/LUCIANA | C7: 1 | D7: 22 | E7: 10.5 | F7: =SUM(D7:E7) -> 32.5 | G7: =IF(IF(F7>=$J$4*0.6,3*(((F7/$J$4)*100-60)/(100-60))+4,3*(F7/($J$4*0.6))+1)>7,7,IF(F7>=$J$4*0.6,3*(((F7/$J$4)*100-60)/(100-60))+4,3*(F7/($J$4*0.6))+1)) -> 3.8508772
A8: 21566004-4 | B8: BRIONES/MEZA/DIEGO ANTONIO | C8: 2 | D8: 16 | E8: 5 | F8: =SUM(D8:E8) -> 21 | G8: =IF(IF(F8>=$J$4*0.6,3*(((F8/$J$4)*100-60)/(100-60))+4,3*(F8/($J$4*0.6))+1)>7,7,IF(F8>=$J$4*0.6,3*(((F8/$J$4)*100-60)/(100-60))+4,3*(F8/($J$4*0.6))+1)) -> 2.8421053
A9: 21896364-1 | B9: BUSTAMANTE/CARTAGENA/VANESSA EMILIA | C9: 2 | D9: 21 | E9: 15 | F9: =SUM(D9:E9) -> 36 | G9: =IF(IF(F9>=$J$4*0.6,3*(((F9/$J$4)*100-60)/(100-60))+4,3*(F9/($J$4*0.6))+1)>7,7,IF(F9>=$J$4*0.6,3*(((F9/$J$4)*100-60)/(100-60))+4,3*(F9/($J$4*0.6))+1)) -> 4.2368421 | H9: 1
A10: 21149692-4 | B10: CAÑETE/OCAMPO/ROSARIO PAZ | C10: 2 | D10: 26 | E10: 15.5 | F10: =SUM(D10:E10) -> 41.5 | G10: =IF(IF(F10>=$J$4*0.6,3*(((F10/$J$4)*100-60)/(100-60))+4,3*(F10/($J$4*0.6))+1)>7,7,IF(F10>=$J$4*0.6,3*(((F10/$J$4)*100-60)/(100-60))+4,3*(F10/($J$4*0.6))+1)) -> 4.9605263
A11: 22030122-2 | B11: CARO/TRONCOSO/MARTINA LORETO | C11: 2
A12: 21840696-3 | B12: CHADE/ARIAS/MARIO EDUARDO | C12: 2 | D12: 21 | E12: 7 | F12: =SUM(D12:E12) -> 28 | G12: =IF(IF(F12>=$J$4*0.6,3*(((F12/$J$4)*100-60)/(100-60))+4,3*(F12/($J$4*0.6))+1)>7,7,IF(F12>=$J$4*0.6,3*(((F12/$J$4)*100-60)/(100-60))+4,3*(F12/($J$4*0.6))+1)) -> 3.4561404 | H12: 1
A13: 21559935-3 | B13: DIAZ/ALLAIN/PABLO ANDRES | C13: 2 | D13: 18 | E13: 11.5 | F13: =SUM(D13:E13) -> 29.5 | G13: =IF(IF(F13>=$J$4*0.6,3*(((F13/$J$4)*100-60)/(100-60))+4,3*(F13/($J$4*0.6))+1)>7,7,IF(F13>=$J$4*0.6,3*(((F13/$J$4)*100-60)/(100-60))+4,3*(F13/($J$4*0.6))+1)) -> 3.5877193
A14: 21988754-K | B14: DIAZ/FORNI/FERNANDA JESUS | C14: 2 | F14: =SUM(D14:E14) -> 0 | G14: =IF(IF(F14>=$J$4*0.6,3*(((F14/$J$4)*100-60)/(100-60))+4,3*(F14/($J$4*0.6))+1)>7,7,IF(F14>=$J$4*0.6,3*(((F14/$J$4)*100-60)/(100-60))+4,3*(F14/($J$4*0.6))+1)) -> 1
A15: 22046076-2 | B15: DIEZ/MORENO/MAGDALENA ISABEL | C15: 2 | D15: 27 | E15: 7 | F15: =SUM(D15:E15) -> 34 | G15: =IF(IF(F15>=$J$4*0.6,3*(((F15/$J$4)*100-60)/(100-60))+4,3*(F15/($J$4*0.6))+1)>7,7,IF(F15>=$J$4*0.6,3*(((F15/$J$4)*100-60)/(100-60))+4,3*(F15/($J$4*0.6))+1)) -> 3.9824561
A16: 21557420-2 | B16: ENCINA/DONOSO/FLORENCIA ALMENDRA | C16: 1 | D16: 19 | E16: 11.75 | F16: =SUM(D16:E16) -> 30.75 | G16: =IF(IF(F16>=$J$4*0.6,3*(((F16/$J$4)*100-60)/(100-60))+4,3*(F16/($J$4*0.6))+1)>7,7,IF(F16>=$J$4*0.6,3*(((F16/$J$4)*100-60)/(100-60))+4,3*(F16/($J$4*0.6))+1)) -> 3.6973684 | H16: 1
A17: 21840694-7 | B17: ESCOBAR/QUEZADA/VALENTINA PAZ | C17: 1
A18: 21268200-4 | B18: GARCIA-HUIDOBRO/FUENZALIDA/SANTIAGO TOMAS | C18: 1
A19: 21833671-K | B19: GARCIA/OLIVA/JAVIERA IGNACIA | C19: 1 | D19: 22 | E19: 11 | F19: =SUM(D19:E19) -> 33 | G19: =IF(IF(F19>=$J$4*0.6,3*(((F19/$J$4)*100-60)/(100-60))+4,3*(F19/($J$4*0.6))+1)>7,7,IF(F19>=$J$4*0.6,3*(((F19/$J$4)*100-60)/(100-60))+4,3*(F19/($J$4*0.6))+1)) -> 3.8947368 | H19: 1
A20: 21893593-1 | B20: GARRIGA/ARGANDOÑA/BENJAMIN IAIR | C20: 2 | D20: 10 | E20: 3 | F20: =SUM(D20:E20) -> 13 | G20: =IF(IF(F20>=$J$4*0.6,3*(((F20/$J$4)*100-60)/(100-60))+4,3*(F20/($J$4*0.6))+1)>7,7,IF(F20>=$J$4*0.6,3*(((F20/$J$4)*100-60)/(100-60))+4,3*(F20/($J$4*0.6))+1)) -> 2.1403509
A21: 22082471-3 | B21: GIESLER/SOTO/EMILY THERESA | C21: 1
A22: 21769435-3 | B22: GOMEZ/GONZALEZ/DOMINGA ANTONIA | C22: 1 | D22: 19 | E22: 11.5 | F22: =SUM(D22:E22) -> 30.5 | G22: =IF(IF(F22>=$J$4*0.6,3*(((F22/$J$4)*100-60)/(100-60))+4,3*(F22/($J$4*0.6))+1)>7,7,IF(F22>=$J$4*0.6,3*(((F22/$J$4)*100-60)/(100-60))+4,3*(F22/($J$4*0.6))+1)) -> 3.6754386 | H22: 1
A23: 21678275-5 | B23: GONZALEZ/ALCERRECA/SOFIA TEODORA | C23: 1 | D23: 16 | E23: 5 | F23: =SUM(D23:E23) -> 21 | G23: =IF(IF(F23>=$J$4*0.6,3*(((F23/$J$4)*100-60)/(100-60))+4,3*(F23/($J$4*0.6))+1)>7,7,IF(F23>=$J$4*0.6,3*(((F23/$J$4)*100-60)/(100-60))+4,3*(F23/($J$4*0.6))+1)) -> 2.8421053
A24: 21905344-4 | B24: GORDON/GARCIA/MARIA JESUS | C24: 1 | D24: 20 | E24: 15.5 | F24: =SUM(D24:E24) -> 35.5 | G24: =IF(IF(F24>=$J$4*0.6,3*(((F24/$J$4)*100-60)/(100-60))+4,3*(F24/($J$4*0.6))+1)>7,7,IF(F24>=$J$4*0.6,3*(((F24/$J$4)*100-60)/(100-60))+4,3*(F24/($J$4*0.6))+1)) -> 4.1710526
A25: 21865263-8 | B25: HENRIQUEZ/NAWRATH/KALA | C25: 2 | D25: 26 | E25: 12.5 | F25: =SUM(D25:E25) -> 38.5 | G25: =IF(IF(F25>=$J$4*0.6,3*(((F25/$J$4)*100-60)/(100-60))+4,3*(F25/($J$4*0.6))+1)>7,7,IF(F25>=$J$4*0.6,3*(((F25/$J$4)*100-60)/(100-60))+4,3*(F25/($J$4*0.6))+1)) -> 4.5657895
A26: 21816695-4 | B26: HERRERA/PADILLA/LAURA ISABEL | C26: 2 | D26: 20 | E26: 14.5 | F26: =SUM(D26:E26) -> 34.5 | G26: =IF(IF(F26>=$J$4*0.6,3*(((F26/$J$4)*100-60)/(100-60))+4,3*(F26/($J$4*0.6))+1)>7,7,IF(F26>=$J$4*0.6,3*(((F26/$J$4)*100-60)/(100-60))+4,3*(F26/($J$4*0.6))+1)) -> 4.0394737
A27: 22011859-2 | B27: HOWARD/PEREZ/CRISTOBAL ANDRES | C27: 2 | D27: 19 | E27: 13 | F27: =SUM(D27:E27) -> 32 | G27: =IF(IF(F27>=$J$4*0.6,3*(((F27/$J$4)*100-60)/(100-60))+4,3*(F27/($J$4*0.6))+1)>7,7,IF(F27>=$J$4*0.6,3*(((F27/$J$4)*100-60)/(100-60))+4,3*(F27/($J$4*0.6))+1)) -> 3.8070175
A28: 21624852-K | B28: IZQUIERDO/MONTES/RAFAEL IGNACIO | C28: 2 | D28: 11 | E28: 0.5 | F28: =SUM(D28:E28) -> 11.5 | G28: =IF(IF(F28>=$J$4*0.6,3*(((F28/$J$4)*100-60)/(100-60))+4,3*(F28/($J$4*0.6))+1)>7,7,IF(F28>=$J$4*0.6,3*(((F28/$J$4)*100-60)/(100-60))+4,3*(F28/($J$4*0.6))+1)) -> 2.0087719
A29: 21845775-4 | B29: JIMENEZ/ANDREU/VICTORIA PAZ | C29: 1
A30: 21678194-5 | B30: JULLIAN/EYZAGUIRRE/BARBARA | C30: 2
A31: 21853700-6 | B31: LATORRE/AHUMADA/JOSEFA | C31: 2 | D31: 23 | E31: 10 | F31: =SUM(D31:E31) -> 33 | G31: =IF(IF(F31>=$J$4*0.6,3*(((F31/$J$4)*100-60)/(100-60))+4,3*(F31/($J$4*0.6))+1)>7,7,IF(F31>=$J$4*0.6,3*(((F31/$J$4)*100-60)/(100-60))+4,3*(F31/($J$4*0.6))+1)) -> 3.8947368
A32: 21527204-4 | B32: LAVIN/VALLEJOS/IGNACIA MARIA | C32: 2 | D32: 22 | E32: 10 | F32: =SUM(D32:E32) -> 32 | G32: =IF(IF(F32>=$J$4*0.6,3*(((F32/$J$4)*100-60)/(100-60))+4,3*(F32/($J$4*0.6))+1)>7,7,IF(F32>=$J$4*0.6,3*(((F32/$J$4)*100-60)/(100-60))+4,3*(F32/($J$4*0.6))+1)) -> 3.8070175
A33: 21923918-1 | B33: LIM/ARIAS/FLORENCIA AUGUSTA | C33: 2 | D33: 21 | E33: 13 | F33: =SUM(D33:E33) -> 34 | G33: =IF(IF(F33>=$J$4*0.6,3*(((F33/$J$4)*100-60)/(100-60))+4,3*(F33/($J$4*0.6))+1)>7,7,IF(F33>=$J$4*0.6,3*(((F33/$J$4)*100-60)/(100-60))+4,3*(F33/($J$4*0.6))+1)) -> 3.9824561 | H33: 1
A34: 21611454-K | B34: LOPEZ/RETAMAL/JOSEFINA ESPERANZA | C34: 1
A35: 21713214-2 | B35: LOPEZ/THAYER/GABRIEL AMAI | C35: 1
A36: 21760460-5 | B36: MALDONADO/ARCE/SOFIA ANTONIA | C36: 1 | D36: 21 | E36: 8 | F36: =SUM(D36:E36) -> 29 | G36: =IF(IF(F36>=$J$4*0.6,3*(((F36/$J$4)*100-60)/(100-60))+4,3*(F36/($J$4*0.6))+1)>7,7,IF(F36>=$J$4*0.6,3*(((F36/$J$4)*100-60)/(100-60))+4,3*(F36/($J$4*0.6))+1)) -> 3.5438596
A37: 21833415-6 | B37: MARTINEZ/AGUILAR/SEBASTIAN PABLO | C37: 1 | D37: 20 | E37: 10 | F37: =SUM(D37:E37) -> 30 | G37: =IF(IF(F37>=$J$4*0.6,3*(((F37/$J$4)*100-60)/(100-60))+4,3*(F37/($J$4*0.6))+1)>7,7,IF(F37>=$J$4*0.6,3*(((F37/$J$4)*100-60)/(100-60))+4,3*(F37/($J$4*0.6))+1)) -> 3.6315789
A38: 21926350-3 | B38: MARTINEZ/LETELIER/PABLO | C38: 2
A39: 21940672-K | B39: MATURANA/FUENTES/ALEX DANIEL | C39: 1
A40: 21473332-3 | B40: MILLACURA/VALENZUELA/BENJAMIN PABLO | C40: 2 | D40: 18 | E40: 8.5 | F40: =SUM(D40:E40) -> 26.5 | G40: =IF(IF(F40>=$J$4*0.6,3*(((F40/$J$4)*100-60)/(100-60))+4,3*(F40/($J$4*0.6))+1)>7,7,IF(F40>=$J$4*0.6,3*(((F40/$J$4)*100-60)/(100-60))+4,3*(F40/($J$4*0.6))+1)) -> 3.3245614
...
